Workbook

Sheet QC,QA제외
A1: SM_SQA | U1: 완료
A2: ■ 제조원가
A3: 품질경영실품질보증3팀 | N3: 2023.07 | O3: 2023.08 | P3: 2023.09 | Q3: 2023.1 | R3: 2023.11 | S3: 2023.12 | V3: =15/14 -> 1.0714286 | AB3: =16/15 -> 1.0666667
A4: 계정 | B4: 예산통제항목 | C4: 비목 성격 | D4: 계정코드 | E4: 예산통제항목 | F4: 2024 예산 | G4: 2024 실적 | H4: 2024.01 | I4: 2024.02 | J4: 2024.03 | K4: 2024.04 | L4: 2024.05 | M4: 2024.06 | N4: 2024.07 | O4: 2024.08 | P4: 2024.09 | Q4: 2024.1 | R4: 2024.11 | S4: 2024.12 | T4: 2025년 예산 | U4: 2025 합계 | V4: 2025.01 | W4: 2025.02 | X4: 2025.03 | Y4: 2025.04 | Z4: 2025.05 | AA4: 2025.06 | AB4: 2025.07 | AC4: 2025.08 | AD4: 2025.09 | AE4: 2025.1 | AF4: 2025.11 | AG4: 2025.12 | AH4: 2026 | AI4: 2026.01 | AJ4: 2026.02 | AK4: 2026.03 | AL4: 2026.04 | AM4: 2026.05 | AN4: 2026.06 | AO4: 2026.07 | AP4: 2026.08 | AQ4: 2026.09 | AR4: 2026.1 | AS4: 2026.11 | AT4: 2026.12 | AU4: 1Q | AV4: 2Q | AW4: 3Q | AX4: 4Q | AY4: 2027 | AZ4: 2028 | BA4: 2029 | BB4: 수립근거 | BC4: 물가 상승률 반영 여부 | BD4: 인원 반영 예산 | BE4: 2021 실적 | BF4: 2022 실적 | BG4: 2023 실적 | BH4: 2024 실적(E)
A5: Ⅰ.원료비 | B5: - | U5: =SUM(V5:AG5) -> 0 | BC5: 포캐스트 연동
A6: 원료비 | B6: - | BC6: X
A7: Ⅱ.재료비 | B7: - | BC7: 포캐스트 연동
A8: 재료비 | B8: - | BC8: X
A9: Ⅲ.노무비 | B9: -
A10: 1.임원급여 | B10: - | BC10: X
A11: 임원급여(제조) | B11: 인건비(기본) | C11: 고정비 | D11: 5102110 | E11: BT432 | BC11: X
A12: 임원상여금(제조) | B12: 인건비(충당) | C12: 고정비 | D12: 5102120 | E12: BT440 | BC12: X
A13: 2.급료와임금 | B13: - | BC13: X
A14: 급료와임금(제조) | B14: 인건비(기본) | C14: 고정비 | D14: 5102210 | E14: BT432 | BB14: 25년 15명/ 26년 17명 / 27년 17명 / 28년 17명 / 29년 17명 | BC14: O
A15: 상여금(제조) | B15: 인건비(충당) | C15: 고정비 | D15: 5102220 | E15: BT440 | BB15: 25년 15명/ 26년 17명 / 27년 17명 / 28년 17명 / 29년 17명 | BC15: O
A16: 학비보조금(제조) | B16: 인건비(기본) | C16: 고정비 | D16: 5102230 | E16: BT432 | BC16: X
A17: 시간외근무수당(제조) | B17: 인건비(추가) | C17: 변동비 | D17: 5102240 | E17: BT436 | BB17: 25년 15명/ 26년 17명 / 27년 17명 / 28년 17명 / 29년 17명 | BC17: O
A18: 휴가보상금(제조) | B18: 인건비(기본) | C18: 고정비 | D18: 5102250 | E18: BT432 | BC18: X
A19: 시상비(제조) | B19: 인건비(추가) | C19: 고정비 | D19: 5102260 | E19: BT436 | BC19: X
A20: 제수당(제조) | B20: 인건비(기본) | C20: 고정비 | D20: 5102280 | E20: BT432 | BC20: X
A21: 일시급여(제조) | B21: 인건비(추가) | C21: 고정비 | D21: 5102290 | E21: BT436 | BC21: X
A22: 3.퇴직급여전입액 | B22: - | BC22: X
A23: 퇴직급여충당금전입액(제조) | B23: 인건비(충당) | C23: 고정비 | D23: 5102410 | E23: BT440 | BC23: X
A24: 퇴직위로금(제조) | B24: - | C24: 고정비 | D24: 5102420 | E24: BT436 | BB24: 최나영 수석 2028-07-01 임금피크제 시작 | BC24: X
A25: 퇴직급여-확정기여형(제조) | C25: 고정비 | D25: 5102430 | BC25: X
A26: Ⅳ.제조경비 | B26: - | F26: 165653824 | G26: =G27+G46+G52+G60+G68+G79+G88+G100+G107+G115+G118+G128+G130+G138+G140+G146+G149+G158+G163+G168+G173 -> 116234132 | H26: =H27+H46+H52+H60+H68+H79+H88+H100+H107+H115+H118+H128+H130+H138+H140+H146+H149+H158+H163+H168+H173 -> 9038022 | I26: =I27+I46+I52+I60+I68+I79+I88+I100+I107+I115+I118+I128+I130+I138+I140+I146+I149+I158+I163+I168+I173 -> 10073459 | J26: =J27+J46+J52+J60+J68+J79+J88+J100+J107+J115+J118+J128+J130+J138+J140+J146+J149+J158+J163+J168+J173 -> 9395487 | K26: =K27+K46+K52+K60+K68+K79+K88+K100+K107+K115+K118+K128+K130+K138+K140+K146+K149+K158+K163+K168+K173 -> 13831192 | L26: =L27+L46+L52+L60+L68+L79+L88+L100+L107+L115+L118+L128+L130+L138+L140+L146+L149+L158+L163+L168+L173 -> 11404351 | M26: =M27+M46+M52+M60+M68+M79+M88+M100+M107+M115+M118+M128+M130+M138+M140+M146+M149+M158+M163+M168+M173 -> 8674192 | N26: =N27+N46+N52+N60+N68+N79+N88+N100+N107+N115+N118+N128+N130+N138+N140+N146+N149+N158+N163+N168+N173 -> 9108576 | ... S26: =S27+S46+S52+S60+S68+S79+S88+S100+S107+S115+S118+S128+S130+S138+S140+S146+S149+S158+S163+S168+S173 -> 9188473 | T26: 6.2625953e+08 | U26: =U27+U46+U52+U60+U68+U79+U88+U100+U107+U115+U118+U128+U130+U138+U140+U146+U149+U158+U163+U168+U173 -> 2.4780349e+08 | V26: =V27+V46+V52+V60+V68+V79+V88+V100+V107+V115+V118+V128+V130+V138+V140+V146+V149+V158+V163+V168+V173 -> 9403142 | W26: =W27+W46+W52+W60+W68+W79+W88+W100+W107+W115+W118+W128+W130+W138+W140+W146+W149+W158+W163+W168+W173 -> 10698878 | X26: =X27+X46+X52+X60+X68+X79+X88+X100+X107+X115+X118+X128+X130+X138+X140+X146+X149+X158+X163+X168+X173 -> 10698717 | Y26: =Y27+Y46+Y52+Y60+Y68+Y79+Y88+Y100+Y107+Y115+Y118+Y128+Y130+Y138+Y140+Y146+Y149+Y158+Y163+Y168+Y173 -> 12850339 | Z26: =Z27+Z46+Z52+Z60+Z68+Z79+Z88+Z100+Z107+Z115+Z118+Z128+Z130+Z138+Z140+Z146+Z149+Z158+Z163+Z168+Z173 -> 10563058 | AA26: =AA27+AA46+AA52+AA60+AA68+AA79+AA88+AA100+AA107+AA115+AA118+AA128+AA130+AA138+AA140+AA146+AA149+AA158+AA163+AA168+AA173 -> 88876935 | AB26: =AB27+AB46+AB52+AB60+AB68+AB79+AB88+AB100+AB107+AB115+AB118+AB128+AB130+AB138+AB140+AB146+AB149+AB158+AB163+AB168+AB173 -> 23118736 | ... AT26: =AT27+AT46+AT52+AT60+AT68+AT79+AT88+AT100+AT107+AT115+AT118+AT128+AT130+AT138+AT140+AT146+AT149+AT158+AT163+AT168+AT173 -> 1.0909662e+09 | AU26: =SUM(AI26:AK26) -> 3.3895633e+09 | AV26: =SUM(AL26:AN26) -> 2949041638 | AW26: =SUM(AO26:AQ26) -> 3266033814 | AX26: =SUM(AR26:AT26) -> 2984981274 | AY26: =AY27+AY46+AY52+AY60+AY68+AY79+AY88+AY100+AY107+AY115+AY118+AY128+AY130+AY138+AY140+AY146+AY149+AY158+AY163+AY168+AY173 -> 1.2910026e+10 | AZ26: =AZ27+AZ46+AZ52+AZ60+AZ68+AZ79+AZ88+AZ100+AZ107+AZ115+AZ118+AZ128+AZ130+AZ138+AZ140+AZ146+AZ149+AZ158+AZ163+AZ168+AZ173 -> 1.3246453e+10 | BA26: =BA27+BA46+BA52+BA60+BA68+BA79+BA88+BA100+BA107+BA115+BA118+BA128+BA130+BA138+BA140+BA146+BA149+BA158+BA163+BA168+BA173 -> 1.3599701e+10 | BC26: 연도별 5% 증가 | BE26: =BE27+BE46+BE52+BE60+BE68+BE79+BE88+BE100+BE107+BE115+BE118+BE128+BE130+BE138+BE140+BE146+BE149+BE158+BE163+BE168+BE173 -> 0 | BF26: 79169476 | BG26: 130128127 | BH26: =G26 -> 116234132
A27: 1.복리후생비 | B27: - | F27: 106972500 | G27: =SUM(G28:G45) -> 101943919 | H27: =SUM(H28:H45) -> 8192785 | I27: =SUM(I28:I45) -> 8540309 | J27: =SUM(J28:J45) -> 8389540 | K27: =SUM(K28:K45) -> 12425015 | L27: =SUM(L28:L45) -> 8959701 | M27: =SUM(M28:M45) -> 7914070 | N27: =SUM(N28:N45) -> 8338457 | ... S27: =SUM(S28:S45) -> 8237736 | T27: 1.0831421e+08 | U27: =SUM(U28:U45) -> 1.1009165e+08 | V27: =SUM(V28:V45) -> 8137510 | W27: =SUM(W28:W45) -> 7477184 | X27: =SUM(X28:X45) -> 8336902 | Y27: =SUM(Y28:Y45) -> 11685478 | Z27: =SUM(Z28:Z45) -> 9416663 | AA27: 8798158.8 | AB27: 9373291.9 | AC27: 9373292.9 | AD27: 9373292.9 | AE27: 9373291.9 | AF27: 9373292.9 | AG27: 9373292.9 | AH27: =SUM(AH28:AH45) -> 559277544 | AI27: =SUM(AI28:AI45) -> 45781462 | AJ27: =SUM(AJ28:AJ45) -> 45781462 | AK27: =SUM(AK28:AK45) -> 46031462 | AL27: =SUM(AL28:AL45) -> 47781462 | AM27: =SUM(AM28:AM45) -> 45781462 | AN27: =SUM(AN28:AN45) -> 46031462 | AO27: =SUM(AO28:AO45) -> 45781462 | ... AT27: =SUM(AT28:AT45) -> 46031462 | AU27: =SUM(AI27:AK27) -> 137594386 | AV27: =SUM(AL27:AN27) -> 139594386 | AW27: =SUM(AO27:AQ27) -> 144494386 | AX27: =SUM(AR27:AT27) -> 137594386 | AY27: =SUM(AY28:AY45) -> 5.7742884e+08 | AZ27: =SUM(AZ28:AZ45) -> 5.964877e+08 | BA27: =SUM(BA28:BA45) -> 6.1649951e+08 | BC27: X | BE27: =SUM(BE28:BE45) -> 0 | BF27: 58138039 | BG27: 101037105 | BH27: =G27 -> 101943919
A28: 복리후생비-통근비(제조) | B28: 통근비(제조) | C28: 고정비 | D28: 5103260 | E28: BT327 | F28: 0 | G28: =SUM(H28:S28) -> 0 | H28: =IFERROR(INDEX('[1]2024'!$A:$Q,MATCH($A$3&$D28,'[1]2024'!$B:$B,0),MATCH(H$4,'[1]2024'!$2:$2,0)),0)+IFERROR(INDEX('[1]2024'!$A:$Q,MATCH($B$3&$D28,'[1]2024'!$B:$B,0),MATCH(H$4,'[1]2024'!$2:$2,0)),0)++IFERROR(INDEX('[1]2024'!$A:$Q,MATCH($C$3&$D28,'[1]2024'!$B:$B,0),MATCH(H$4,'[1]2024'!$2:$2,0)),0)++IFERROR(INDEX('[1]2024'!$A:$Q,MATCH($D$3&$D28,'[1]2024'!$B:$B,0),MATCH(H$4,'[1]2024'!$2:$2,0)),0) -> 0 | I28: =IFERROR(INDEX('[1]2024'!$A:$Q,MATCH($A$3&$D28,'[1]2024'!$B:$B,0),MATCH(I$4,'[1]2024'!$2:$2,0)),0)+IFERROR(INDEX('[1]2024'!$A:$Q,MATCH($B$3&$D28,'[1]2024'!$B:$B,0),MATCH(I$4,'[1]2024'!$2:$2,0)),0)++IFERROR(INDEX('[1]2024'!$A:$Q,MATCH($C$3&$D28,'[1]2024'!$B:$B,0),MATCH(I$4,'[1]2024'!$2:$2,0)),0)++IFERROR(INDEX('[1]2024'!$A:$Q,MATCH($D$3&$D28,'[1]2024'!$B:$B,0),MATCH(I$4,'[1]2024'!$2:$2,0)),0) -> 0 | J28: =IFERROR(INDEX('[1]2024'!$A:$Q,MATCH($A$3&$D28,'[1]2024'!$B:$B,0),MATCH(J$4,'[1]2024'!$2:$2,0)),0)+IFERROR(INDEX('[1]2024'!$A:$Q,MATCH($B$3&$D28,'[1]2024'!$B:$B,0),MATCH(J$4,'[1]2024'!$2:$2,0)),0)++IFERROR(INDEX('[1]2024'!$A:$Q,MATCH($C$3&$D28,'[1]2024'!$B:$B,0),MATCH(J$4,'[1]2024'!$2:$2,0)),0)++IFERROR(INDEX('[1]2024'!$A:$Q,MATCH($D$3&$D28,'[1]2024'!$B:$B,0),MATCH(J$4,'[1]2024'!$2:$2,0)),0) -> 0 | K28: =IFERROR(INDEX('[1]2024'!$A:$Q,MATCH($A$3&$D28,'[1]2024'!$B:$B,0),MATCH(K$4,'[1]2024'!$2:$2,0)),0)+IFERROR(INDEX('[1]2024'!$A:$Q,MATCH($B$3&$D28,'[1]2024'!$B:$B,0),MATCH(K$4,'[1]2024'!$2:$2,0)),0)++IFERROR(INDEX('[1]2024'!$A:$Q,MATCH($C$3&$D28,'[1]2024'!$B:$B,0),MATCH(K$4,'[1]2024'!$2:$2,0)),0)++IFERROR(INDEX('[1]2024'!$A:$Q,MATCH($D$3&$D28,'[1]2024'!$B:$B,0),MATCH(K$4,'[1]2024'!$2:$2,0)),0) -> 0 | L28: =IFERROR(INDEX('[1]2024'!$A:$Q,MATCH($A$3&$D28,'[1]2024'!$B:$B,0),MATCH(L$4,'[1]2024'!$2:$2,0)),0)+IFERROR(INDEX('[1]2024'!$A:$Q,MATCH($B$3&$D28,'[1]2024'!$B:$B,0),MATCH(L$4,'[1]2024'!$2:$2,0)),0)++IFERROR(INDEX('[1]2024'!$A:$Q,MATCH($C$3&$D28,'[1]2024'!$B:$B,0),MATCH(L$4,'[1]2024'!$2:$2,0)),0)++IFERROR(INDEX('[1]2024'!$A:$Q,MATCH($D$3&$D28,'[1]2024'!$B:$B,0),MATCH(L$4,'[1]2024'!$2:$2,0)),0) -> 0 | M28: =IFERROR(INDEX('[1]2024'!$A:$Q,MATCH($A$3&$D28,'[1]2024'!$B:$B,0),MATCH(M$4,'[1]2024'!$2:$2,0)),0)+IFERROR(INDEX('[1]2024'!$A:$Q,MATCH($B$3&$D28,'[1]2024'!$B:$B,0),MATCH(M$4,'[1]2024'!$2:$2,0)),0)++IFERROR(INDEX('[1]2024'!$A:$Q,MATCH($C$3&$D28,'[1]2024'!$B:$B,0),MATCH(M$4,'[1]2024'!$2:$2,0)),0)++IFERROR(INDEX('[1]2024'!$A:$Q,MATCH($D$3&$D28,'[1]2024'!$B:$B,0),MATCH(M$4,'[1]2024'!$2:$2,0)),0) -> 0 | N28: =IFERROR(INDEX('[1]2024'!$A:$Q,MATCH($A$3&$D28,'[1]2024'!$B:$B,0),MATCH(N$4,'[1]2024'!$2:$2,0)),0)+IFERROR(INDEX('[1]2024'!$A:$Q,MATCH($B$3&$D28,'[1]2024'!$B:$B,0),MATCH(N$4,'[1]2024'!$2:$2,0)),0)++IFERROR(INDEX('[1]2024'!$A:$Q,MATCH($C$3&$D28,'[1]2024'!$B:$B,0),MATCH(N$4,'[1]2024'!$2:$2,0)),0)++IFERROR(INDEX('[1]2024'!$A:$Q,MATCH($D$3&$D28,'[1]2024'!$B:$B,0),MATCH(N$4,'[1]2024'!$2:$2,0)),0) -> 0 | O28: =IFERROR(INDEX('[1]2024'!$A:$Q,MATCH($A$3&$D28,'[1]2024'!$B:$B,0),MATCH(O$4,'[1]2024'!$2:$2,0)),0)+IFERROR(INDEX('[1]2024'!$A:$Q,MATCH($B$3&$D28,'[1]2024'!$B:$B,0),MATCH(O$4,'[1]2024'!$2:$2,0)),0)++IFERROR(INDEX('[1]2024'!$A:$Q,MATCH($C$3&$D28,'[1]2024'!$B:$B,0),MATCH(O$4,'[1]2024'!$2:$2,0)),0)++IFERROR(INDEX('[1]2024'!$A:$Q,MATCH($D$3&$D28,'[1]2024'!$B:$B,0),MATCH(O$4,'[1]2024'!$2:$2,0)),0) -> 0 | ... S28: =IFERROR(INDEX('[1]2024'!$A:$Q,MATCH($A$3&$D28,'[1]2024'!$B:$B,0),MATCH(S$4,'[1]2024'!$2:$2,0)),0)+IFERROR(INDEX('[1]2024'!$A:$Q,MATCH($B$3&$D28,'[1]2024'!$B:$B,0),MATCH(S$4,'[1]2024'!$2:$2,0)),0)++IFERROR(INDEX('[1]2024'!$A:$Q,MATCH($C$3&$D28,'[1]2024'!$B:$B,0),MATCH(S$4,'[1]2024'!$2:$2,0)),0)++IFERROR(INDEX('[1]2024'!$A:$Q,MATCH($D$3&$D28,'[1]2024'!$B:$B,0),MATCH(S$4,'[1]2024'!$2:$2,0)),0) -> 0 | T28: 0 | U28: =SUM(V28:AG28) -> 0 | V28: 0 | W28: 0 | X28: 0 | Y28: 0 | Z28: 0 | AA28: 0 | AB28: 0 | AC28: 0 | AD28: 0 | AE28: 0 | AF28: 0 | AG28: 0 | AH28: =송도공장장!AH28+제조팀!AH28+송도밸리데이션팀!AH28+송도생산지원팀!AH28+송도설비관리팀!AH28 -> 91200000 | AI28: =송도공장장!AI28+제조팀!AI28+송도밸리데이션팀!AI28+송도생산지원팀!AI28+송도설비관리팀!AI28 -> 7600000 | AJ28: =송도공장장!AJ28+제조팀!AJ28+송도밸리데이션팀!AJ28+송도생산지원팀!AJ28+송도설비관리팀!AJ28 -> 7600000 | AK28: =송도공장장!AK28+제조팀!AK28+송도밸리데이션팀!AK28+송도생산지원팀!AK28+송도설비관리팀!AK28 -> 7600000 | AL28: =송도공장장!AL28+제조팀!AL28+송도밸리데이션팀!AL28+송도생산지원팀!AL28+송도설비관리팀!AL28 -> 7600000 | AM28: =송도공장장!AM28+제조팀!AM28+송도밸리데이션팀!AM28+송도생산지원팀!AM28+송도설비관리팀!AM28 -> 7600000 | AN28: =송도공장장!AN28+제조팀!AN28+송도밸리데이션팀!AN28+송도생산지원팀!AN28+송도설비관리팀!AN28 -> 7600000 | AO28: =송도공장장!AO28+제조팀!AO28+송도밸리데이션팀!AO28+송도생산지원팀!AO28+송도설비관리팀!AO28 -> 7600000 | ... AT28: =송도공장장!AT28+제조팀!AT28+송도밸리데이션팀!AT28+송도생산지원팀!AT28+송도설비관리팀!AT28 -> 7600000 | AU28: =SUM(AI28:AK28) -> 22800000 | AV28: =SUM(AL28:AN28) -> 22800000 | AW28: =SUM(AO28:AQ28) -> 22800000 | AX28: =SUM(AR28:AT28) -> 22800000 | AY28: =IF($BC28="O",1.05*$AH28,$AH28) -> 91200000 | AZ28: =IF($BC28="O",1.05*$AY28,$AY28) -> 91200000 | BA28: =IF($BC28="O",1.05*$AZ28,$AZ28) -> 91200000 | BC28: X | BE28: 0 | BF28: 0 | BG28: 0 | BH28: =G28 -> 0
A29: 복리후생비-직원이전비(제조) | B29: 직원이전비(제조) | C29: 고정비 | D29: 5103250 | E29: BT307 | F29: 0 | G29: =SUM(H29:S29) -> 0 | H29: =IFERROR(INDEX('[1]2024'!$A:$Q,MATCH($A$3&$D29,'[1]2024'!$B:$B,0),MATCH(H$4,'[1]2024'!$2:$2,0)),0)+IFERROR(INDEX('[1]2024'!$A:$Q,MATCH($B$3&$D29,'[1]2024'!$B:$B,0),MATCH(H$4,'[1]2024'!$2:$2,0)),0)++IFERROR(INDEX('[1]2024'!$A:$Q,MATCH($C$3&$D29,'[1]2024'!$B:$B,0),MATCH(H$4,'[1]2024'!$2:$2,0)),0)++IFERROR(INDEX('[1]2024'!$A:$Q,MATCH($D$3&$D29,'[1]2024'!$B:$B,0),MATCH(H$4,'[1]2024'!$2:$2,0)),0) -> 0 | I29: =IFERROR(INDEX('[1]2024'!$A:$Q,MATCH($A$3&$D29,'[1]2024'!$B:$B,0),MATCH(I$4,'[1]2024'!$2:$2,0)),0)+IFERROR(INDEX('[1]2024'!$A:$Q,MATCH($B$3&$D29,'[1]2024'!$B:$B,0),MATCH(I$4,'[1]2024'!$2:$2,0)),0)++IFERROR(INDEX('[1]2024'!$A:$Q,MATCH($C$3&$D29,'[1]2024'!$B:$B,0),MATCH(I$4,'[1]2024'!$2:$2,0)),0)++IFERROR(INDEX('[1]2024'!$A:$Q,MATCH($D$3&$D29,'[1]2024'!$B:$B,0),MATCH(I$4,'[1]2024'!$2:$2,0)),0) -> 0 | J29: =IFERROR(INDEX('[1]2024'!$A:$Q,MATCH($A$3&$D29,'[1]2024'!$B:$B,0),MATCH(J$4,'[1]2024'!$2:$2,0)),0)+IFERROR(INDEX('[1]2024'!$A:$Q,MATCH($B$3&$D29,'[1]2024'!$B:$B,0),MATCH(J$4,'[1]2024'!$2:$2,0)),0)++IFERROR(INDEX('[1]2024'!$A:$Q,MATCH($C$3&$D29,'[1]2024'!$B:$B,0),MATCH(J$4,'[1]2024'!$2:$2,0)),0)++IFERROR(INDEX('[1]2024'!$A:$Q,MATCH($D$3&$D29,'[1]2024'!$B:$B,0),MATCH(J$4,'[1]2024'!$2:$2,0)),0) -> 0 | K29: =IFERROR(INDEX('[1]2024'!$A:$Q,MATCH($A$3&$D29,'[1]2024'!$B:$B,0),MATCH(K$4,'[1]2024'!$2:$2,0)),0)+IFERROR(INDEX('[1]2024'!$A:$Q,MATCH($B$3&$D29,'[1]2024'!$B:$B,0),MATCH(K$4,'[1]2024'!$2:$2,0)),0)++IFERROR(INDEX('[1]2024'!$A:$Q,MATCH($C$3&$D29,'[1]2024'!$B:$B,0),MATCH(K$4,'[1]2024'!$2:$2,0)),0)++IFERROR(INDEX('[1]2024'!$A:$Q,MATCH($D$3&$D29,'[1]2024'!$B:$B,0),MATCH(K$4,'[1]2024'!$2:$2,0)),0) -> 0 | L29: =IFERROR(INDEX('[1]2024'!$A:$Q,MATCH($A$3&$D29,'[1]2024'!$B:$B,0),MATCH(L$4,'[1]2024'!$2:$2,0)),0)+IFERROR(INDEX('[1]2024'!$A:$Q,MATCH($B$3&$D29,'[1]2024'!$B:$B,0),MATCH(L$4,'[1]2024'!$2:$2,0)),0)++IFERROR(INDEX('[1]2024'!$A:$Q,MATCH($C$3&$D29,'[1]2024'!$B:$B,0),MATCH(L$4,'[1]2024'!$2:$2,0)),0)++IFERROR(INDEX('[1]2024'!$A:$Q,MATCH($D$3&$D29,'[1]2024'!$B:$B,0),MATCH(L$4,'[1]2024'!$2:$2,0)),0) -> 0 | M29: =IFERROR(INDEX('[1]2024'!$A:$Q,MATCH($A$3&$D29,'[1]2024'!$B:$B,0),MATCH(M$4,'[1]2024'!$2:$2,0)),0)+IFERROR(INDEX('[1]2024'!$A:$Q,MATCH($B$3&$D29,'[1]2024'!$B:$B,0),MATCH(M$4,'[1]2024'!$2:$2,0)),0)++IFERROR(INDEX('[1]2024'!$A:$Q,MATCH($C$3&$D29,'[1]2024'!$B:$B,0),MATCH(M$4,'[1]2024'!$2:$2,0)),0)++IFERROR(INDEX('[1]2024'!$A:$Q,MATCH($D$3&$D29,'[1]2024'!$B:$B,0),MATCH(M$4,'[1]2024'!$2:$2,0)),0) -> 0 | N29: =IFERROR(INDEX('[1]2024'!$A:$Q,MATCH($A$3&$D29,'[1]2024'!$B:$B,0),MATCH(N$4,'[1]2024'!$2:$2,0)),0)+IFERROR(INDEX('[1]2024'!$A:$Q,MATCH($B$3&$D29,'[1]2024'!$B:$B,0),MATCH(N$4,'[1]2024'!$2:$2,0)),0)++IFERROR(INDEX('[1]2024'!$A:$Q,MATCH($C$3&$D29,'[1]2024'!$B:$B,0),MATCH(N$4,'[1]2024'!$2:$2,0)),0)++IFERROR(INDEX('[1]2024'!$A:$Q,MATCH($D$3&$D29,'[1]2024'!$B:$B,0),MATCH(N$4,'[1]2024'!$2:$2,0)),0) -> 0 | O29: =IFERROR(INDEX('[1]2024'!$A:$Q,MATCH($A$3&$D29,'[1]2024'!$B:$B,0),MATCH(O$4,'[1]2024'!$2:$2,0)),0)+IFERROR(INDEX('[1]2024'!$A:$Q,MATCH($B$3&$D29,'[1]2024'!$B:$B,0),MATCH(O$4,'[1]2024'!$2:$2,0)),0)++IFERROR(INDEX('[1]2024'!$A:$Q,MATCH($C$3&$D29,'[1]2024'!$B:$B,0),MATCH(O$4,'[1]2024'!$2:$2,0)),0)++IFERROR(INDEX('[1]2024'!$A:$Q,MATCH($D$3&$D29,'[1]2024'!$B:$B,0),MATCH(O$4,'[1]2024'!$2:$2,0)),0) -> 0 | ... S29: =IFERROR(INDEX('[1]2024'!$A:$Q,MATCH($A$3&$D29,'[1]2024'!$B:$B,0),MATCH(S$4,'[1]2024'!$2:$2,0)),0)+IFERROR(INDEX('[1]2024'!$A:$Q,MATCH($B$3&$D29,'[1]2024'!$B:$B,0),MATCH(S$4,'[1]2024'!$2:$2,0)),0)++IFERROR(INDEX('[1]2024'!$A:$Q,MATCH($C$3&$D29,'[1]2024'!$B:$B,0),MATCH(S$4,'[1]2024'!$2:$2,0)),0)++IFERROR(INDEX('[1]2024'!$A:$Q,MATCH($D$3&$D29,'[1]2024'!$B:$B,0),MATCH(S$4,'[1]2024'!$2:$2,0)),0) -> 0 | T29: 0 | U29: =SUM(V29:AG29) -> 0 | V29: 0 | W29: 0 | X29: 0 | Y29: 0 | Z29: 0 | AA29: 0 | AB29: 0 | AC29: 0 | AD29: 0 | AE29: 0 | AF29: 0 | AG29: 0 | AH29: =송도공장장!AH29+제조팀!AH29+송도밸리데이션팀!AH29+송도생산지원팀!AH29+송도설비관리팀!AH29 -> 0 | AI29: =송도공장장!AI29+제조팀!AI29+송도밸리데이션팀!AI29+송도생산지원팀!AI29+송도설비관리팀!AI29 -> 0 | AJ29: =송도공장장!AJ29+제조팀!AJ29+송도밸리데이션팀!AJ29+송도생산지원팀!AJ29+송도설비관리팀!AJ29 -> 0 | AK29: =송도공장장!AK29+제조팀!AK29+송도밸리데이션팀!AK29+송도생산지원팀!AK29+송도설비관리팀!AK29 -> 0 | AL29: =송도공장장!AL29+제조팀!AL29+송도밸리데이션팀!AL29+송도생산지원팀!AL29+송도설비관리팀!AL29 -> 0 | AM29: =송도공장장!AM29+제조팀!AM29+송도밸리데이션팀!AM29+송도생산지원팀!AM29+송도설비관리팀!AM29 -> 0 | AN29: =송도공장장!AN29+제조팀!AN29+송도밸리데이션팀!AN29+송도생산지원팀!AN29+송도설비관리팀!AN29 -> 0 | AO29: =송도공장장!AO29+제조팀!AO29+송도밸리데이션팀!AO29+송도생산지원팀!AO29+송도설비관리팀!AO29 -> 0 | ... AT29: =송도공장장!AT29+제조팀!AT29+송도밸리데이션팀!AT29+송도생산지원팀!AT29+송도설비관리팀!AT29 -> 0 | AU29: =SUM(AI29:AK29) -> 0 | AV29: =SUM(AL29:AN29) -> 0 | AW29: =SUM(AO29:AQ29) -> 0 | AX29: =SUM(AR29:AT29) -> 0 | AY29: =IF($BC29="O",1.05*$AH29,$AH29) -> 0 | AZ29: =IF($BC29="O",1.05*$AY29,$AY29) -> 0 | BA29: =IF($BC29="O",1.05*$AZ29,$AZ29) -> 0 | BC29: X | BE29: 0 | BF29: 0 | BG29: 1390000 | BH29: =G29 -> 0
A30: 복리후생비-당직비(제조) | B30: 당직비(제조) | C30: 고정비 | D30: 5103240 | E30: BT073 | F30: 0 | G30: =SUM(H30:S30) -> 0 | H30: =IFERROR(INDEX('[1]2024'!$A:$Q,MATCH($A$3&$D30,'[1]2024'!$B:$B,0),MATCH(H$4,'[1]2024'!$2:$2,0)),0)+IFERROR(INDEX('[1]2024'!$A:$Q,MATCH($B$3&$D30,'[1]2024'!$B:$B,0),MATCH(H$4,'[1]2024'!$2:$2,0)),0)++IFERROR(INDEX('[1]2024'!$A:$Q,MATCH($C$3&$D30,'[1]2024'!$B:$B,0),MATCH(H$4,'[1]2024'!$2:$2,0)),0)++IFERROR(INDEX('[1]2024'!$A:$Q,MATCH($D$3&$D30,'[1]2024'!$B:$B,0),MATCH(H$4,'[1]2024'!$2:$2,0)),0) -> 0 | I30: =IFERROR(INDEX('[1]2024'!$A:$Q,MATCH($A$3&$D30,'[1]2024'!$B:$B,0),MATCH(I$4,'[1]2024'!$2:$2,0)),0)+IFERROR(INDEX('[1]2024'!$A:$Q,MATCH($B$3&$D30,'[1]2024'!$B:$B,0),MATCH(I$4,'[1]2024'!$2:$2,0)),0)++IFERROR(INDEX('[1]2024'!$A:$Q,MATCH($C$3&$D30,'[1]2024'!$B:$B,0),MATCH(I$4,'[1]2024'!$2:$2,0)),0)++IFERROR(INDEX('[1]2024'!$A:$Q,MATCH($D$3&$D30,'[1]2024'!$B:$B,0),MATCH(I$4,'[1]2024'!$2:$2,0)),0) -> 0 | J30: =IFERROR(INDEX('[1]2024'!$A:$Q,MATCH($A$3&$D30,'[1]2024'!$B:$B,0),MATCH(J$4,'[1]2024'!$2:$2,0)),0)+IFERROR(INDEX('[1]2024'!$A:$Q,MATCH($B$3&$D30,'[1]2024'!$B:$B,0),MATCH(J$4,'[1]2024'!$2:$2,0)),0)++IFERROR(INDEX('[1]2024'!$A:$Q,MATCH($C$3&$D30,'[1]2024'!$B:$B,0),MATCH(J$4,'[1]2024'!$2:$2,0)),0)++IFERROR(INDEX('[1]2024'!$A:$Q,MATCH($D$3&$D30,'[1]2024'!$B:$B,0),MATCH(J$4,'[1]2024'!$2:$2,0)),0) -> 0 | K30: =IFERROR(INDEX('[1]2024'!$A:$Q,MATCH($A$3&$D30,'[1]2024'!$B:$B,0),MATCH(K$4,'[1]2024'!$2:$2,0)),0)+IFERROR(INDEX('[1]2024'!$A:$Q,MATCH($B$3&$D30,'[1]2024'!$B:$B,0),MATCH(K$4,'[1]2024'!$2:$2,0)),0)++IFERROR(INDEX('[1]2024'!$A:$Q,MATCH($C$3&$D30,'[1]2024'!$B:$B,0),MATCH(K$4,'[1]2024'!$2:$2,0)),0)++IFERROR(INDEX('[1]2024'!$A:$Q,MATCH($D$3&$D30,'[1]2024'!$B:$B,0),MATCH(K$4,'[1]2024'!$2:$2,0)),0) -> 0 | L30: =IFERROR(INDEX('[1]2024'!$A:$Q,MATCH($A$3&$D30,'[1]2024'!$B:$B,0),MATCH(L$4,'[1]2024'!$2:$2,0)),0)+IFERROR(INDEX('[1]2024'!$A:$Q,MATCH($B$3&$D30,'[1]2024'!$B:$B,0),MATCH(L$4,'[1]2024'!$2:$2,0)),0)++IFERROR(INDEX('[1]2024'!$A:$Q,MATCH($C$3&$D30,'[1]2024'!$B:$B,0),MATCH(L$4,'[1]2024'!$2:$2,0)),0)++IFERROR(INDEX('[1]2024'!$A:$Q,MATCH($D$3&$D30,'[1]2024'!$B:$B,0),MATCH(L$4,'[1]2024'!$2:$2,0)),0) -> 0 | M30: =IFERROR(INDEX('[1]2024'!$A:$Q,MATCH($A$3&$D30,'[1]2024'!$B:$B,0),MATCH(M$4,'[1]2024'!$2:$2,0)),0)+IFERROR(INDEX('[1]2024'!$A:$Q,MATCH($B$3&$D30,'[1]2024'!$B:$B,0),MATCH(M$4,'[1]2024'!$2:$2,0)),0)++IFERROR(INDEX('[1]2024'!$A:$Q,MATCH($C$3&$D30,'[1]2024'!$B:$B,0),MATCH(M$4,'[1]2024'!$2:$2,0)),0)++IFERROR(INDEX('[1]2024'!$A:$Q,MATCH($D$3&$D30,'[1]2024'!$B:$B,0),MATCH(M$4,'[1]2024'!$2:$2,0)),0) -> 0 | N30: =IFERROR(INDEX('[1]2024'!$A:$Q,MATCH($A$3&$D30,'[1]2024'!$B:$B,0),MATCH(N$4,'[1]2024'!$2:$2,0)),0)+IFERROR(INDEX('[1]2024'!$A:$Q,MATCH($B$3&$D30,'[1]2024'!$B:$B,0),MATCH(N$4,'[1]2024'!$2:$2,0)),0)++IFERROR(INDEX('[1]2024'!$A:$Q,MATCH($C$3&$D30,'[1]2024'!$B:$B,0),MATCH(N$4,'[1]2024'!$2:$2,0)),0)++IFERROR(INDEX('[1]2024'!$A:$Q,MATCH($D$3&$D30,'[1]2024'!$B:$B,0),MATCH(N$4,'[1]2024'!$2:$2,0)),0) -> 0 | O30: =IFERROR(INDEX('[1]2024'!$A:$Q,MATCH($A$3&$D30,'[1]2024'!$B:$B,0),MATCH(O$4,'[1]2024'!$2:$2,0)),0)+IFERROR(INDEX('[1]2024'!$A:$Q,MATCH($B$3&$D30,'[1]2024'!$B:$B,0),MATCH(O$4,'[1]2024'!$2:$2,0)),0)++IFERROR(INDEX('[1]2024'!$A:$Q,MATCH($C$3&$D30,'[1]2024'!$B:$B,0),MATCH(O$4,'[1]2024'!$2:$2,0)),0)++IFERROR(INDEX('[1]2024'!$A:$Q,MATCH($D$3&$D30,'[1]2024'!$B:$B,0),MATCH(O$4,'[1]2024'!$2:$2,0)),0) -> 0 | ... S30: =IFERROR(INDEX('[1]2024'!$A:$Q,MATCH($A$3&$D30,'[1]2024'!$B:$B,0),MATCH(S$4,'[1]2024'!$2:$2,0)),0)+IFERROR(INDEX('[1]2024'!$A:$Q,MATCH($B$3&$D30,'[1]2024'!$B:$B,0),MATCH(S$4,'[1]2024'!$2:$2,0)),0)++IFERROR(INDEX('[1]2024'!$A:$Q,MATCH($C$3&$D30,'[1]2024'!$B:$B,0),MATCH(S$4,'[1]2024'!$2:$2,0)),0)++IFERROR(INDEX('[1]2024'!$A:$Q,MATCH($D$3&$D30,'[1]2024'!$B:$B,0),MATCH(S$4,'[1]2024'!$2:$2,0)),0) -> 0 | T30: 0 | U30: =SUM(V30:AG30) -> 0 | V30: 0 | W30: 0 | X30: 0 | Y30: 0 | Z30: 0 | AA30: 0 | AB30: 0 | AC30: 0 | AD30: 0 | AE30: 0 | AF30: 0 | AG30: 0 | AH30: =송도공장장!AH30+제조팀!AH30+송도밸리데이션팀!AH30+송도생산지원팀!AH30+송도설비관리팀!AH30 -> 0 | AI30: =송도공장장!AI30+제조팀!AI30+송도밸리데이션팀!AI30+송도생산지원팀!AI30+송도설비관리팀!AI30 -> 0 | AJ30: =송도공장장!AJ30+제조팀!AJ30+송도밸리데이션팀!AJ30+송도생산지원팀!AJ30+송도설비관리팀!AJ30 -> 0 | AK30: =송도공장장!AK30+제조팀!AK30+송도밸리데이션팀!AK30+송도생산지원팀!AK30+송도설비관리팀!AK30 -> 0 | AL30: =송도공장장!AL30+제조팀!AL30+송도밸리데이션팀!AL30+송도생산지원팀!AL30+송도설비관리팀!AL30 -> 0 | AM30: =송도공장장!AM30+제조팀!AM30+송도밸리데이션팀!AM30+송도생산지원팀!AM30+송도설비관리팀!AM30 -> 0 | AN30: =송도공장장!AN30+제조팀!AN30+송도밸리데이션팀!AN30+송도생산지원팀!AN30+송도설비관리팀!AN30 -> 0 | AO30: =송도공장장!AO30+제조팀!AO30+송도밸리데이션팀!AO30+송도생산지원팀!AO30+송도설비관리팀!AO30 -> 0 | ... AT30: =송도공장장!AT30+제조팀!AT30+송도밸리데이션팀!AT30+송도생산지원팀!AT30+송도설비관리팀!AT30 -> 0 | AU30: =SUM(AI30:AK30) -> 0 | AV30: =SUM(AL30:AN30) -> 0 | AW30: =SUM(AO30:AQ30) -> 0 | AX30: =SUM(AR30:AT30) -> 0 | AY30: =IF($BC30="O",1.05*$AH30,$AH30) -> 0 | AZ30: =IF($BC30="O",1.05*$AY30,$AY30) -> 0 | BA30: =IF($BC30="O",1.05*$AZ30,$AZ30) -> 0 | BC30: X | BE30: 0 | BF30: 0 | BG30: 0 | BH30: =G30 -> 0
A31: 복리후생비-복지시설이용비(제조) | B31: 복지시설이용비(제조) | C31: 고정비 | D31: 5103230 | E31: BT106 | F31: 0 | G31: =SUM(H31:S31) -> 0 | H31: =IFERROR(INDEX('[1]2024'!$A:$Q,MATCH($A$3&$D31,'[1]2024'!$B:$B,0),MATCH(H$4,'[1]2024'!$2:$2,0)),0)+IFERROR(INDEX('[1]2024'!$A:$Q,MATCH($B$3&$D31,'[1]2024'!$B:$B,0),MATCH(H$4,'[1]2024'!$2:$2,0)),0)++IFERROR(INDEX('[1]2024'!$A:$Q,MATCH($C$3&$D31,'[1]2024'!$B:$B,0),MATCH(H$4,'[1]2024'!$2:$2,0)),0)++IFERROR(INDEX('[1]2024'!$A:$Q,MATCH($D$3&$D31,'[1]2024'!$B:$B,0),MATCH(H$4,'[1]2024'!$2:$2,0)),0) -> 0 | I31: =IFERROR(INDEX('[1]2024'!$A:$Q,MATCH($A$3&$D31,'[1]2024'!$B:$B,0),MATCH(I$4,'[1]2024'!$2:$2,0)),0)+IFERROR(INDEX('[1]2024'!$A:$Q,MATCH($B$3&$D31,'[1]2024'!$B:$B,0),MATCH(I$4,'[1]2024'!$2:$2,0)),0)++IFERROR(INDEX('[1]2024'!$A:$Q,MATCH($C$3&$D31,'[1]2024'!$B:$B,0),MATCH(I$4,'[1]2024'!$2:$2,0)),0)++IFERROR(INDEX('[1]2024'!$A:$Q,MATCH($D$3&$D31,'[1]2024'!$B:$B,0),MATCH(I$4,'[1]2024'!$2:$2,0)),0) -> 0 | J31: =IFERROR(INDEX('[1]2024'!$A:$Q,MATCH($A$3&$D31,'[1]2024'!$B:$B,0),MATCH(J$4,'[1]2024'!$2:$2,0)),0)+IFERROR(INDEX('[1]2024'!$A:$Q,MATCH($B$3&$D31,'[1]2024'!$B:$B,0),MATCH(J$4,'[1]2024'!$2:$2,0)),0)++IFERROR(INDEX('[1]2024'!$A:$Q,MATCH($C$3&$D31,'[1]2024'!$B:$B,0),MATCH(J$4,'[1]2024'!$2:$2,0)),0)++IFERROR(INDEX('[1]2024'!$A:$Q,MATCH($D$3&$D31,'[1]2024'!$B:$B,0),MATCH(J$4,'[1]2024'!$2:$2,0)),0) -> 0 | K31: =IFERROR(INDEX('[1]2024'!$A:$Q,MATCH($A$3&$D31,'[1]2024'!$B:$B,0),MATCH(K$4,'[1]2024'!$2:$2,0)),0)+IFERROR(INDEX('[1]2024'!$A:$Q,MATCH($B$3&$D31,'[1]2024'!$B:$B,0),MATCH(K$4,'[1]2024'!$2:$2,0)),0)++IFERROR(INDEX('[1]2024'!$A:$Q,MATCH($C$3&$D31,'[1]2024'!$B:$B,0),MATCH(K$4,'[1]2024'!$2:$2,0)),0)++IFERROR(INDEX('[1]2024'!$A:$Q,MATCH($D$3&$D31,'[1]2024'!$B:$B,0),MATCH(K$4,'[1]2024'!$2:$2,0)),0) -> 0 | L31: =IFERROR(INDEX('[1]2024'!$A:$Q,MATCH($A$3&$D31,'[1]2024'!$B:$B,0),MATCH(L$4,'[1]2024'!$2:$2,0)),0)+IFERROR(INDEX('[1]2024'!$A:$Q,MATCH($B$3&$D31,'[1]2024'!$B:$B,0),MATCH(L$4,'[1]2024'!$2:$2,0)),0)++IFERROR(INDEX('[1]2024'!$A:$Q,MATCH($C$3&$D31,'[1]2024'!$B:$B,0),MATCH(L$4,'[1]2024'!$2:$2,0)),0)++IFERROR(INDEX('[1]2024'!$A:$Q,MATCH($D$3&$D31,'[1]2024'!$B:$B,0),MATCH(L$4,'[1]2024'!$2:$2,0)),0) -> 0 | M31: =IFERROR(INDEX('[1]2024'!$A:$Q,MATCH($A$3&$D31,'[1]2024'!$B:$B,0),MATCH(M$4,'[1]2024'!$2:$2,0)),0)+IFERROR(INDEX('[1]2024'!$A:$Q,MATCH($B$3&$D31,'[1]2024'!$B:$B,0),MATCH(M$4,'[1]2024'!$2:$2,0)),0)++IFERROR(INDEX('[1]2024'!$A:$Q,MATCH($C$3&$D31,'[1]2024'!$B:$B,0),MATCH(M$4,'[1]2024'!$2:$2,0)),0)++IFERROR(INDEX('[1]2024'!$A:$Q,MATCH($D$3&$D31,'[1]2024'!$B:$B,0),MATCH(M$4,'[1]2024'!$2:$2,0)),0) -> 0 | N31: =IFERROR(INDEX('[1]2024'!$A:$Q,MATCH($A$3&$D31,'[1]2024'!$B:$B,0),MATCH(N$4,'[1]2024'!$2:$2,0)),0)+IFERROR(INDEX('[1]2024'!$A:$Q,MATCH($B$3&$D31,'[1]2024'!$B:$B,0),MATCH(N$4,'[1]2024'!$2:$2,0)),0)++IFERROR(INDEX('[1]2024'!$A:$Q,MATCH($C$3&$D31,'[1]2024'!$B:$B,0),MATCH(N$4,'[1]2024'!$2:$2,0)),0)++IFERROR(INDEX('[1]2024'!$A:$Q,MATCH($D$3&$D31,'[1]2024'!$B:$B,0),MATCH(N$4,'[1]2024'!$2:$2,0)),0) -> 0 | O31: =IFERROR(INDEX('[1]2024'!$A:$Q,MATCH($A$3&$D31,'[1]2024'!$B:$B,0),MATCH(O$4,'[1]2024'!$2:$2,0)),0)+IFERROR(INDEX('[1]2024'!$A:$Q,MATCH($B$3&$D31,'[1]2024'!$B:$B,0),MATCH(O$4,'[1]2024'!$2:$2,0)),0)++IFERROR(INDEX('[1]2024'!$A:$Q,MATCH($C$3&$D31,'[1]2024'!$B:$B,0),MATCH(O$4,'[1]2024'!$2:$2,0)),0)++IFERROR(INDEX('[1]2024'!$A:$Q,MATCH($D$3&$D31,'[1]2024'!$B:$B,0),MATCH(O$4,'[1]2024'!$2:$2,0)),0) -> 0 | ... S31: =IFERROR(INDEX('[1]2024'!$A:$Q,MATCH($A$3&$D31,'[1]2024'!$B:$B,0),MATCH(S$4,'[1]2024'!$2:$2,0)),0)+IFERROR(INDEX('[1]2024'!$A:$Q,MATCH($B$3&$D31,'[1]2024'!$B:$B,0),MATCH(S$4,'[1]2024'!$2:$2,0)),0)++IFERROR(INDEX('[1]2024'!$A:$Q,MATCH($C$3&$D31,'[1]2024'!$B:$B,0),MATCH(S$4,'[1]2024'!$2:$2,0)),0)++IFERROR(INDEX('[1]2024'!$A:$Q,MATCH($D$3&$D31,'[1]2024'!$B:$B,0),MATCH(S$4,'[1]2024'!$2:$2,0)),0) -> 0 | T31: 0 | U31: =SUM(V31:AG31) -> 0 | V31: 0 | W31: 0 | X31: 0 | Y31: 0 | Z31: 0 | AA31: 0 | AB31: 0 | AC31: 0 | AD31: 0 | AE31: 0 | AF31: 0 | AG31: 0 | AH31: =송도공장장!AH31+제조팀!AH31+송도밸리데이션팀!AH31+송도생산지원팀!AH31+송도설비관리팀!AH31 -> 0 | AI31: =송도공장장!AI31+제조팀!AI31+송도밸리데이션팀!AI31+송도생산지원팀!AI31+송도설비관리팀!AI31 -> 0 | AJ31: =송도공장장!AJ31+제조팀!AJ31+송도밸리데이션팀!AJ31+송도생산지원팀!AJ31+송도설비관리팀!AJ31 -> 0 | AK31: =송도공장장!AK31+제조팀!AK31+송도밸리데이션팀!AK31+송도생산지원팀!AK31+송도설비관리팀!AK31 -> 0 | AL31: =송도공장장!AL31+제조팀!AL31+송도밸리데이션팀!AL31+송도생산지원팀!AL31+송도설비관리팀!AL31 -> 0 | AM31: =송도공장장!AM31+제조팀!AM31+송도밸리데이션팀!AM31+송도생산지원팀!AM31+송도설비관리팀!AM31 -> 0 | AN31: =송도공장장!AN31+제조팀!AN31+송도밸리데이션팀!AN31+송도생산지원팀!AN31+송도설비관리팀!AN31 -> 0 | AO31: =송도공장장!AO31+제조팀!AO31+송도밸리데이션팀!AO31+송도생산지원팀!AO31+송도설비관리팀!AO31 -> 0 | ... AT31: =송도공장장!AT31+제조팀!AT31+송도밸리데이션팀!AT31+송도생산지원팀!AT31+송도설비관리팀!AT31 -> 0 | AU31: =SUM(AI31:AK31) -> 0 | AV31: =SUM(AL31:AN31) -> 0 | AW31: =SUM(AO31:AQ31) -> 0 | AX31: =SUM(AR31:AT31) -> 0 | AY31: =IF($BC31="O",1.05*$AH31,$AH31) -> 0 | AZ31: =IF($BC31="O",1.05*$AY31,$AY31) -> 0 | BA31: =IF($BC31="O",1.05*$AZ31,$AZ31) -> 0 | BC31: X | BE31: 0 | BF31: 0 | BG31: 0 | BH31: =G31 -> 0
A32: 복리후생비-후생비(제조) | B32: 후생비 | C32: 고정비 | D32: 5103220 | E32: BT386 | F32: 0 | G32: =SUM(H32:S32) -> 0 | H32: =IFERROR(INDEX('[1]2024'!$A:$Q,MATCH($A$3&$D32,'[1]2024'!$B:$B,0),MATCH(H$4,'[1]2024'!$2:$2,0)),0)+IFERROR(INDEX('[1]2024'!$A:$Q,MATCH($B$3&$D32,'[1]2024'!$B:$B,0),MATCH(H$4,'[1]2024'!$2:$2,0)),0)++IFERROR(INDEX('[1]2024'!$A:$Q,MATCH($C$3&$D32,'[1]2024'!$B:$B,0),MATCH(H$4,'[1]2024'!$2:$2,0)),0)++IFERROR(INDEX('[1]2024'!$A:$Q,MATCH($D$3&$D32,'[1]2024'!$B:$B,0),MATCH(H$4,'[1]2024'!$2:$2,0)),0) -> 0 | I32: =IFERROR(INDEX('[1]2024'!$A:$Q,MATCH($A$3&$D32,'[1]2024'!$B:$B,0),MATCH(I$4,'[1]2024'!$2:$2,0)),0)+IFERROR(INDEX('[1]2024'!$A:$Q,MATCH($B$3&$D32,'[1]2024'!$B:$B,0),MATCH(I$4,'[1]2024'!$2:$2,0)),0)++IFERROR(INDEX('[1]2024'!$A:$Q,MATCH($C$3&$D32,'[1]2024'!$B:$B,0),MATCH(I$4,'[1]2024'!$2:$2,0)),0)++IFERROR(INDEX('[1]2024'!$A:$Q,MATCH($D$3&$D32,'[1]2024'!$B:$B,0),MATCH(I$4,'[1]2024'!$2:$2,0)),0) -> 0 | J32: =IFERROR(INDEX('[1]2024'!$A:$Q,MATCH($A$3&$D32,'[1]2024'!$B:$B,0),MATCH(J$4,'[1]2024'!$2:$2,0)),0)+IFERROR(INDEX('[1]2024'!$A:$Q,MATCH($B$3&$D32,'[1]2024'!$B:$B,0),MATCH(J$4,'[1]2024'!$2:$2,0)),0)++IFERROR(INDEX('[1]2024'!$A:$Q,MATCH($C$3&$D32,'[1]2024'!$B:$B,0),MATCH(J$4,'[1]2024'!$2:$2,0)),0)++IFERROR(INDEX('[1]2024'!$A:$Q,MATCH($D$3&$D32,'[1]2024'!$B:$B,0),MATCH(J$4,'[1]2024'!$2:$2,0)),0) -> 0 | K32: =IFERROR(INDEX('[1]2024'!$A:$Q,MATCH($A$3&$D32,'[1]2024'!$B:$B,0),MATCH(K$4,'[1]2024'!$2:$2,0)),0)+IFERROR(INDEX('[1]2024'!$A:$Q,MATCH($B$3&$D32,'[1]2024'!$B:$B,0),MATCH(K$4,'[1]2024'!$2:$2,0)),0)++IFERROR(INDEX('[1]2024'!$A:$Q,MATCH($C$3&$D32,'[1]2024'!$B:$B,0),MATCH(K$4,'[1]2024'!$2:$2,0)),0)++IFERROR(INDEX('[1]2024'!$A:$Q,MATCH($D$3&$D32,'[1]2024'!$B:$B,0),MATCH(K$4,'[1]2024'!$2:$2,0)),0) -> 0 | L32: =IFERROR(INDEX('[1]2024'!$A:$Q,MATCH($A$3&$D32,'[1]2024'!$B:$B,0),MATCH(L$4,'[1]2024'!$2:$2,0)),0)+IFERROR(INDEX('[1]2024'!$A:$Q,MATCH($B$3&$D32,'[1]2024'!$B:$B,0),MATCH(L$4,'[1]2024'!$2:$2,0)),0)++IFERROR(INDEX('[1]2024'!$A:$Q,MATCH($C$3&$D32,'[1]2024'!$B:$B,0),MATCH(L$4,'[1]2024'!$2:$2,0)),0)++IFERROR(INDEX('[1]2024'!$A:$Q,MATCH($D$3&$D32,'[1]2024'!$B:$B,0),MATCH(L$4,'[1]2024'!$2:$2,0)),0) -> 0 | M32: =IFERROR(INDEX('[1]2024'!$A:$Q,MATCH($A$3&$D32,'[1]2024'!$B:$B,0),MATCH(M$4,'[1]2024'!$2:$2,0)),0)+IFERROR(INDEX('[1]2024'!$A:$Q,MATCH($B$3&$D32,'[1]2024'!$B:$B,0),MATCH(M$4,'[1]2024'!$2:$2,0)),0)++IFERROR(INDEX('[1]2024'!$A:$Q,MATCH($C$3&$D32,'[1]2024'!$B:$B,0),MATCH(M$4,'[1]2024'!$2:$2,0)),0)++IFERROR(INDEX('[1]2024'!$A:$Q,MATCH($D$3&$D32,'[1]2024'!$B:$B,0),MATCH(M$4,'[1]2024'!$2:$2,0)),0) -> 0 | N32: =IFERROR(INDEX('[1]2024'!$A:$Q,MATCH($A$3&$D32,'[1]2024'!$B:$B,0),MATCH(N$4,'[1]2024'!$2:$2,0)),0)+IFERROR(INDEX('[1]2024'!$A:$Q,MATCH($B$3&$D32,'[1]2024'!$B:$B,0),MATCH(N$4,'[1]2024'!$2:$2,0)),0)++IFERROR(INDEX('[1]2024'!$A:$Q,MATCH($C$3&$D32,'[1]2024'!$B:$B,0),MATCH(N$4,'[1]2024'!$2:$2,0)),0)++IFERROR(INDEX('[1]2024'!$A:$Q,MATCH($D$3&$D32,'[1]2024'!$B:$B,0),MATCH(N$4,'[1]2024'!$2:$2,0)),0) -> 0 | O32: =IFERROR(INDEX('[1]2024'!$A:$Q,MATCH($A$3&$D32,'[1]2024'!$B:$B,0),MATCH(O$4,'[1]2024'!$2:$2,0)),0)+IFERROR(INDEX('[1]2024'!$A:$Q,MATCH($B$3&$D32,'[1]2024'!$B:$B,0),MATCH(O$4,'[1]2024'!$2:$2,0)),0)++IFERROR(INDEX('[1]2024'!$A:$Q,MATCH($C$3&$D32,'[1]2024'!$B:$B,0),MATCH(O$4,'[1]2024'!$2:$2,0)),0)++IFERROR(INDEX('[1]2024'!$A:$Q,MATCH($D$3&$D32,'[1]2024'!$B:$B,0),MATCH(O$4,'[1]2024'!$2:$2,0)),0) -> 0 | ... S32: =IFERROR(INDEX('[1]2024'!$A:$Q,MATCH($A$3&$D32,'[1]2024'!$B:$B,0),MATCH(S$4,'[1]2024'!$2:$2,0)),0)+IFERROR(INDEX('[1]2024'!$A:$Q,MATCH($B$3&$D32,'[1]2024'!$B:$B,0),MATCH(S$4,'[1]2024'!$2:$2,0)),0)++IFERROR(INDEX('[1]2024'!$A:$Q,MATCH($C$3&$D32,'[1]2024'!$B:$B,0),MATCH(S$4,'[1]2024'!$2:$2,0)),0)++IFERROR(INDEX('[1]2024'!$A:$Q,MATCH($D$3&$D32,'[1]2024'!$B:$B,0),MATCH(S$4,'[1]2024'!$2:$2,0)),0) -> 0 | T32: 0 | U32: =SUM(V32:AG32) -> 0 | V32: 0 | W32: 0 | X32: 0 | Y32: 0 | Z32: 0 | AA32: 0 | AB32: 0 | AC32: 0 | AD32: 0 | AE32: 0 | AF32: 0 | AG32: 0 | AH32: =송도공장장!AH32+제조팀!AH32+송도밸리데이션팀!AH32+송도생산지원팀!AH32+송도설비관리팀!AH32 -> 48000000 | AI32: =송도공장장!AI32+제조팀!AI32+송도밸리데이션팀!AI32+송도생산지원팀!AI32+송도설비관리팀!AI32 -> 4000000 | AJ32: =송도공장장!AJ32+제조팀!AJ32+송도밸리데이션팀!AJ32+송도생산지원팀!AJ32+송도설비관리팀!AJ32 -> 4000000 | AK32: =송도공장장!AK32+제조팀!AK32+송도밸리데이션팀!AK32+송도생산지원팀!AK32+송도설비관리팀!AK32 -> 4000000 | AL32: =송도공장장!AL32+제조팀!AL32+송도밸리데이션팀!AL32+송도생산지원팀!AL32+송도설비관리팀!AL32 -> 4000000 | AM32: =송도공장장!AM32+제조팀!AM32+송도밸리데이션팀!AM32+송도생산지원팀!AM32+송도설비관리팀!AM32 -> 4000000 | AN32: =송도공장장!AN32+제조팀!AN32+송도밸리데이션팀!AN32+송도생산지원팀!AN32+송도설비관리팀!AN32 -> 4000000 | AO32: =송도공장장!AO32+제조팀!AO32+송도밸리데이션팀!AO32+송도생산지원팀!AO32+송도설비관리팀!AO32 -> 4000000 | ... AT32: =송도공장장!AT32+제조팀!AT32+송도밸리데이션팀!AT32+송도생산지원팀!AT32+송도설비관리팀!AT32 -> 4000000 | AU32: =SUM(AI32:AK32) -> 12000000 | AV32: =SUM(AL32:AN32) -> 12000000 | AW32: =SUM(AO32:AQ32) -> 12000000 | AX32: =SUM(AR32:AT32) -> 12000000 | AY32: =IF($BC32="O",1.05*$AH32,$AH32) -> 48000000 | AZ32: =IF($BC32="O",1.05*$AY32,$AY32) -> 48000000 | BA32: =IF($BC32="O",1.05*$AZ32,$AZ32) -> 48000000 | BC32: X | BE32: 0 | BF32: 0 | BG32: 0 | BH32: =G32 -> 0
A33: 복리후생비-사내경조비(제조) | B33: 복리후생비-사내경조비(제조) | C33: 고정비 | D33: 5103210 | E33: BT111 | F33: 800000 | G33: =SUM(H33:S33) -> 550000 | H33: =IFERROR(INDEX('[1]2024'!$A:$Q,MATCH($A$3&$D33,'[1]2024'!$B:$B,0),MATCH(H$4,'[1]2024'!$2:$2,0)),0)+IFERROR(INDEX('[1]2024'!$A:$Q,MATCH($B$3&$D33,'[1]2024'!$B:$B,0),MATCH(H$4,'[1]2024'!$2:$2,0)),0)++IFERROR(INDEX('[1]2024'!$A:$Q,MATCH($C$3&$D33,'[1]2024'!$B:$B,0),MATCH(H$4,'[1]2024'!$2:$2,0)),0)++IFERROR(INDEX('[1]2024'!$A:$Q,MATCH($D$3&$D33,'[1]2024'!$B:$B,0),MATCH(H$4,'[1]2024'!$2:$2,0)),0) -> 50000 | I33: =IFERROR(INDEX('[1]2024'!$A:$Q,MATCH($A$3&$D33,'[1]2024'!$B:$B,0),MATCH(I$4,'[1]2024'!$2:$2,0)),0)+IFERROR(INDEX('[1]2024'!$A:$Q,MATCH($B$3&$D33,'[1]2024'!$B:$B,0),MATCH(I$4,'[1]2024'!$2:$2,0)),0)++IFERROR(INDEX('[1]2024'!$A:$Q,MATCH($C$3&$D33,'[1]2024'!$B:$B,0),MATCH(I$4,'[1]2024'!$2:$2,0)),0)++IFERROR(INDEX('[1]2024'!$A:$Q,MATCH($D$3&$D33,'[1]2024'!$B:$B,0),MATCH(I$4,'[1]2024'!$2:$2,0)),0) -> 0 | J33: =IFERROR(INDEX('[1]2024'!$A:$Q,MATCH($A$3&$D33,'[1]2024'!$B:$B,0),MATCH(J$4,'[1]2024'!$2:$2,0)),0)+IFERROR(INDEX('[1]2024'!$A:$Q,MATCH($B$3&$D33,'[1]2024'!$B:$B,0),MATCH(J$4,'[1]2024'!$2:$2,0)),0)++IFERROR(INDEX('[1]2024'!$A:$Q,MATCH($C$3&$D33,'[1]2024'!$B:$B,0),MATCH(J$4,'[1]2024'!$2:$2,0)),0)++IFERROR(INDEX('[1]2024'!$A:$Q,MATCH($D$3&$D33,'[1]2024'!$B:$B,0),MATCH(J$4,'[1]2024'!$2:$2,0)),0) -> 0 | K33: =IFERROR(INDEX('[1]2024'!$A:$Q,MATCH($A$3&$D33,'[1]2024'!$B:$B,0),MATCH(K$4,'[1]2024'!$2:$2,0)),0)+IFERROR(INDEX('[1]2024'!$A:$Q,MATCH($B$3&$D33,'[1]2024'!$B:$B,0),MATCH(K$4,'[1]2024'!$2:$2,0)),0)++IFERROR(INDEX('[1]2024'!$A:$Q,MATCH($C$3&$D33,'[1]2024'!$B:$B,0),MATCH(K$4,'[1]2024'!$2:$2,0)),0)++IFERROR(INDEX('[1]2024'!$A:$Q,MATCH($D$3&$D33,'[1]2024'!$B:$B,0),MATCH(K$4,'[1]2024'!$2:$2,0)),0) -> 0 | L33: =IFERROR(INDEX('[1]2024'!$A:$Q,MATCH($A$3&$D33,'[1]2024'!$B:$B,0),MATCH(L$4,'[1]2024'!$2:$2,0)),0)+IFERROR(INDEX('[1]2024'!$A:$Q,MATCH($B$3&$D33,'[1]2024'!$B:$B,0),MATCH(L$4,'[1]2024'!$2:$2,0)),0)++IFERROR(INDEX('[1]2024'!$A:$Q,MATCH($C$3&$D33,'[1]2024'!$B:$B,0),MATCH(L$4,'[1]2024'!$2:$2,0)),0)++IFERROR(INDEX('[1]2024'!$A:$Q,MATCH($D$3&$D33,'[1]2024'!$B:$B,0),MATCH(L$4,'[1]2024'!$2:$2,0)),0) -> 50000 | M33: =IFERROR(INDEX('[1]2024'!$A:$Q,MATCH($A$3&$D33,'[1]2024'!$B:$B,0),MATCH(M$4,'[1]2024'!$2:$2,0)),0)+IFERROR(INDEX('[1]2024'!$A:$Q,MATCH($B$3&$D33,'[1]2024'!$B:$B,0),MATCH(M$4,'[1]2024'!$2:$2,0)),0)++IFERROR(INDEX('[1]2024'!$A:$Q,MATCH($C$3&$D33,'[1]2024'!$B:$B,0),MATCH(M$4,'[1]2024'!$2:$2,0)),0)++IFERROR(INDEX('[1]2024'!$A:$Q,MATCH($D$3&$D33,'[1]2024'!$B:$B,0),MATCH(M$4,'[1]2024'!$2:$2,0)),0) -> 100000 | N33: =IFERROR(INDEX('[1]2024'!$A:$Q,MATCH($A$3&$D33,'[1]2024'!$B:$B,0),MATCH(N$4,'[1]2024'!$2:$2,0)),0)+IFERROR(INDEX('[1]2024'!$A:$Q,MATCH($B$3&$D33,'[1]2024'!$B:$B,0),MATCH(N$4,'[1]2024'!$2:$2,0)),0)++IFERROR(INDEX('[1]2024'!$A:$Q,MATCH($C$3&$D33,'[1]2024'!$B:$B,0),MATCH(N$4,'[1]2024'!$2:$2,0)),0)++IFERROR(INDEX('[1]2024'!$A:$Q,MATCH($D$3&$D33,'[1]2024'!$B:$B,0),MATCH(N$4,'[1]2024'!$2:$2,0)),0) -> 0 | O33: =IFERROR(INDEX('[1]2024'!$A:$Q,MATCH($A$3&$D33,'[1]2024'!$B:$B,0),MATCH(O$4,'[1]2024'!$2:$2,0)),0)+IFERROR(INDEX('[1]2024'!$A:$Q,MATCH($B$3&$D33,'[1]2024'!$B:$B,0),MATCH(O$4,'[1]2024'!$2:$2,0)),0)++IFERROR(INDEX('[1]2024'!$A:$Q,MATCH($C$3&$D33,'[1]2024'!$B:$B,0),MATCH(O$4,'[1]2024'!$2:$2,0)),0)++IFERROR(INDEX('[1]2024'!$A:$Q,MATCH($D$3&$D33,'[1]2024'!$B:$B,0),MATCH(O$4,'[1]2024'!$2:$2,0)),0) -> 50000 | ... S33: =IFERROR(INDEX('[1]2024'!$A:$Q,MATCH($A$3&$D33,'[1]2024'!$B:$B,0),MATCH(S$4,'[1]2024'!$2:$2,0)),0)+IFERROR(INDEX('[1]2024'!$A:$Q,MATCH($B$3&$D33,'[1]2024'!$B:$B,0),MATCH(S$4,'[1]2024'!$2:$2,0)),0)++IFERROR(INDEX('[1]2024'!$A:$Q,MATCH($C$3&$D33,'[1]2024'!$B:$B,0),MATCH(S$4,'[1]2024'!$2:$2,0)),0)++IFERROR(INDEX('[1]2024'!$A:$Q,MATCH($D$3&$D33,'[1]2024'!$B:$B,0),MATCH(S$4,'[1]2024'!$2:$2,0)),0) -> 0 | T33: 800000 | U33: =SUM(V33:AG33) -> 566667 | V33: 0 | W33: 0 | X33: 50000 | Y33: 50000 | Z33: 0 | AA33: 66667 | AB33: 66666 | AC33: 66667 | AD33: 66667 | AE33: 66666 | AF33: 66667 | AG33: 66667 | AH33: =송도공장장!AH33+제조팀!AH33+송도밸리데이션팀!AH33+송도생산지원팀!AH33+송도설비관리팀!AH33 -> 4960000 | AI33: =송도공장장!AI33+제조팀!AI33+송도밸리데이션팀!AI33+송도생산지원팀!AI33+송도설비관리팀!AI33 -> 330000 | AJ33: =송도공장장!AJ33+제조팀!AJ33+송도밸리데이션팀!AJ33+송도생산지원팀!AJ33+송도설비관리팀!AJ33 -> 330000 | AK33: =송도공장장!AK33+제조팀!AK33+송도밸리데이션팀!AK33+송도생산지원팀!AK33+송도설비관리팀!AK33 -> 580000 | AL33: =송도공장장!AL33+제조팀!AL33+송도밸리데이션팀!AL33+송도생산지원팀!AL33+송도설비관리팀!AL33 -> 330000 | AM33: =송도공장장!AM33+제조팀!AM33+송도밸리데이션팀!AM33+송도생산지원팀!AM33+송도설비관리팀!AM33 -> 330000 | AN33: =송도공장장!AN33+제조팀!AN33+송도밸리데이션팀!AN33+송도생산지원팀!AN33+송도설비관리팀!AN33 -> 580000 | AO33: =송도공장장!AO33+제조팀!AO33+송도밸리데이션팀!AO33+송도생산지원팀!AO33+송도설비관리팀!AO33 -> 330000 | ... AT33: =송도공장장!AT33+제조팀!AT33+송도밸리데이션팀!AT33+송도생산지원팀!AT33+송도설비관리팀!AT33 -> 580000 | AU33: =SUM(AI33:AK33) -> 1240000 | AV33: =SUM(AL33:AN33) -> 1240000 | AW33: =SUM(AO33:AQ33) -> 1240000 | AX33: =SUM(AR33:AT33) -> 1240000 | AY33: =IF($BC33="O",1.05*$AH33,$AH33) -> 4960000 | AZ33: =IF($BC33="O",1.05*$AY33,$AY33) -> 4960000 | BA33: =IF($BC33="O",1.05*$AZ33,$AZ33) -> 4960000 | BC33: X | BE33: 0 | BF33: 700000 | BG33: 550000 | BH33: =G33 -> 550000
A34: 복리후생비-지원보조비(제조) | B34: 준인건비(기본) | C34: 고정비 | D34: 5103190 | E34: BT289 | F34: 1320000 | G34: =SUM(H34:S34) -> 1200500 | H34: =IFERROR(INDEX('[1]2024'!$A:$Q,MATCH($A$3&$D34,'[1]2024'!$B:$B,0),MATCH(H$4,'[1]2024'!$2:$2,0)),0)+IFERROR(INDEX('[1]2024'!$A:$Q,MATCH($B$3&$D34,'[1]2024'!$B:$B,0),MATCH(H$4,'[1]2024'!$2:$2,0)),0)++IFERROR(INDEX('[1]2024'!$A:$Q,MATCH($C$3&$D34,'[1]2024'!$B:$B,0),MATCH(H$4,'[1]2024'!$2:$2,0)),0)++IFERROR(INDEX('[1]2024'!$A:$Q,MATCH($D$3&$D34,'[1]2024'!$B:$B,0),MATCH(H$4,'[1]2024'!$2:$2,0)),0) -> 106690 | I34: =IFERROR(INDEX('[1]2024'!$A:$Q,MATCH($A$3&$D34,'[1]2024'!$B:$B,0),MATCH(I$4,'[1]2024'!$2:$2,0)),0)+IFERROR(INDEX('[1]2024'!$A:$Q,MATCH($B$3&$D34,'[1]2024'!$B:$B,0),MATCH(I$4,'[1]2024'!$2:$2,0)),0)++IFERROR(INDEX('[1]2024'!$A:$Q,MATCH($C$3&$D34,'[1]2024'!$B:$B,0),MATCH(I$4,'[1]2024'!$2:$2,0)),0)++IFERROR(INDEX('[1]2024'!$A:$Q,MATCH($D$3&$D34,'[1]2024'!$B:$B,0),MATCH(I$4,'[1]2024'!$2:$2,0)),0) -> 106690 | J34: =IFERROR(INDEX('[1]2024'!$A:$Q,MATCH($A$3&$D34,'[1]2024'!$B:$B,0),MATCH(J$4,'[1]2024'!$2:$2,0)),0)+IFERROR(INDEX('[1]2024'!$A:$Q,MATCH($B$3&$D34,'[1]2024'!$B:$B,0),MATCH(J$4,'[1]2024'!$2:$2,0)),0)++IFERROR(INDEX('[1]2024'!$A:$Q,MATCH($C$3&$D34,'[1]2024'!$B:$B,0),MATCH(J$4,'[1]2024'!$2:$2,0)),0)++IFERROR(INDEX('[1]2024'!$A:$Q,MATCH($D$3&$D34,'[1]2024'!$B:$B,0),MATCH(J$4,'[1]2024'!$2:$2,0)),0) -> 106690 | K34: =IFERROR(INDEX('[1]2024'!$A:$Q,MATCH($A$3&$D34,'[1]2024'!$B:$B,0),MATCH(K$4,'[1]2024'!$2:$2,0)),0)+IFERROR(INDEX('[1]2024'!$A:$Q,MATCH($B$3&$D34,'[1]2024'!$B:$B,0),MATCH(K$4,'[1]2024'!$2:$2,0)),0)++IFERROR(INDEX('[1]2024'!$A:$Q,MATCH($C$3&$D34,'[1]2024'!$B:$B,0),MATCH(K$4,'[1]2024'!$2:$2,0)),0)++IFERROR(INDEX('[1]2024'!$A:$Q,MATCH($D$3&$D34,'[1]2024'!$B:$B,0),MATCH(K$4,'[1]2024'!$2:$2,0)),0) -> 106690 | L34: =IFERROR(INDEX('[1]2024'!$A:$Q,MATCH($A$3&$D34,'[1]2024'!$B:$B,0),MATCH(L$4,'[1]2024'!$2:$2,0)),0)+IFERROR(INDEX('[1]2024'!$A:$Q,MATCH($B$3&$D34,'[1]2024'!$B:$B,0),MATCH(L$4,'[1]2024'!$2:$2,0)),0)++IFERROR(INDEX('[1]2024'!$A:$Q,MATCH($C$3&$D34,'[1]2024'!$B:$B,0),MATCH(L$4,'[1]2024'!$2:$2,0)),0)++IFERROR(INDEX('[1]2024'!$A:$Q,MATCH($D$3&$D34,'[1]2024'!$B:$B,0),MATCH(L$4,'[1]2024'!$2:$2,0)),0) -> 110240 | M34: =IFERROR(INDEX('[1]2024'!$A:$Q,MATCH($A$3&$D34,'[1]2024'!$B:$B,0),MATCH(M$4,'[1]2024'!$2:$2,0)),0)+IFERROR(INDEX('[1]2024'!$A:$Q,MATCH($B$3&$D34,'[1]2024'!$B:$B,0),MATCH(M$4,'[1]2024'!$2:$2,0)),0)++IFERROR(INDEX('[1]2024'!$A:$Q,MATCH($C$3&$D34,'[1]2024'!$B:$B,0),MATCH(M$4,'[1]2024'!$2:$2,0)),0)++IFERROR(INDEX('[1]2024'!$A:$Q,MATCH($D$3&$D34,'[1]2024'!$B:$B,0),MATCH(M$4,'[1]2024'!$2:$2,0)),0) -> 104480 | N34: =IFERROR(INDEX('[1]2024'!$A:$Q,MATCH($A$3&$D34,'[1]2024'!$B:$B,0),MATCH(N$4,'[1]2024'!$2:$2,0)),0)+IFERROR(INDEX('[1]2024'!$A:$Q,MATCH($B$3&$D34,'[1]2024'!$B:$B,0),MATCH(N$4,'[1]2024'!$2:$2,0)),0)++IFERROR(INDEX('[1]2024'!$A:$Q,MATCH($C$3&$D34,'[1]2024'!$B:$B,0),MATCH(N$4,'[1]2024'!$2:$2,0)),0)++IFERROR(INDEX('[1]2024'!$A:$Q,MATCH($D$3&$D34,'[1]2024'!$B:$B,0),MATCH(N$4,'[1]2024'!$2:$2,0)),0) -> 99560 | O34: =IFERROR(INDEX('[1]2024'!$A:$Q,MATCH($A$3&$D34,'[1]2024'!$B:$B,0),MATCH(O$4,'[1]2024'!$2:$2,0)),0)+IFERROR(INDEX('[1]2024'!$A:$Q,MATCH($B$3&$D34,'[1]2024'!$B:$B,0),MATCH(O$4,'[1]2024'!$2:$2,0)),0)++IFERROR(INDEX('[1]2024'!$A:$Q,MATCH($C$3&$D34,'[1]2024'!$B:$B,0),MATCH(O$4,'[1]2024'!$2:$2,0)),0)++IFERROR(INDEX('[1]2024'!$A:$Q,MATCH($D$3&$D34,'[1]2024'!$B:$B,0),MATCH(O$4,'[1]2024'!$2:$2,0)),0) -> 92840 | ... S34: =IFERROR(INDEX('[1]2024'!$A:$Q,MATCH($A$3&$D34,'[1]2024'!$B:$B,0),MATCH(S$4,'[1]2024'!$2:$2,0)),0)+IFERROR(INDEX('[1]2024'!$A:$Q,MATCH($B$3&$D34,'[1]2024'!$B:$B,0),MATCH(S$4,'[1]2024'!$2:$2,0)),0)++IFERROR(INDEX('[1]2024'!$A:$Q,MATCH($C$3&$D34,'[1]2024'!$B:$B,0),MATCH(S$4,'[1]2024'!$2:$2,0)),0)++IFERROR(INDEX('[1]2024'!$A:$Q,MATCH($D$3&$D34,'[1]2024'!$B:$B,0),MATCH(S$4,'[1]2024'!$2:$2,0)),0) -> 93690 | T34: 1253760 | U34: =SUM(V34:AG34) -> 1216370 | V34: 93560 | W34: 93560 | X34: 95720 | Y34: 97050 | Z34: 105120 | AA34: 104480 | AB34: 104480 | AC34: 104480 | AD34: 104480 | AE34: 104480 | AF34: 104480 | AG34: 104480 | AH34: =송도공장장!AH34+제조팀!AH34+송도밸리데이션팀!AH34+송도생산지원팀!AH34+송도설비관리팀!AH34 -> 3351600 | AI34: =송도공장장!AI34+제조팀!AI34+송도밸리데이션팀!AI34+송도생산지원팀!AI34+송도설비관리팀!AI34 -> 279300 | AJ34: =송도공장장!AJ34+제조팀!AJ34+송도밸리데이션팀!AJ34+송도생산지원팀!AJ34+송도설비관리팀!AJ34 -> 279300 | AK34: =송도공장장!AK34+제조팀!AK34+송도밸리데이션팀!AK34+송도생산지원팀!AK34+송도설비관리팀!AK34 -> 279300 | AL34: =송도공장장!AL34+제조팀!AL34+송도밸리데이션팀!AL34+송도생산지원팀!AL34+송도설비관리팀!AL34 -> 279300 | AM34: =송도공장장!AM34+제조팀!AM34+송도밸리데이션팀!AM34+송도생산지원팀!AM34+송도설비관리팀!AM34 -> 279300 | AN34: =송도공장장!AN34+제조팀!AN34+송도밸리데이션팀!AN34+송도생산지원팀!AN34+송도설비관리팀!AN34 -> 279300 | AO34: =송도공장장!AO34+제조팀!AO34+송도밸리데이션팀!AO34+송도생산지원팀!AO34+송도설비관리팀!AO34 -> 279300 | ... AT34: =송도공장장!AT34+제조팀!AT34+송도밸리데이션팀!AT34+송도생산지원팀!AT34+송도설비관리팀!AT34 -> 279300 | AU34: =SUM(AI34:AK34) -> 837900 | AV34: =SUM(AL34:AN34) -> 837900 | AW34: =SUM(AO34:AQ34) -> 837900 | AX34: =SUM(AR34:AT34) -> 837900 | AY34: =IF($BC34="O",1.05*$AH34,$AH34) -> 3351600 | AZ34: =IF($BC34="O",1.05*$AY34,$AY34) -> 3351600 | BA34: =IF($BC34="O",1.05*$AZ34,$AZ34) -> 3351600 | BB34: 25년 15명/ 26년 17명 / 27년 17명 / 28년 17명 / 29년 17명 | BC34: X | BD34: O | BE34: 0 | BF34: 699530 | BG34: 1221880 | BH34: =G34 -> 1200500
A35: 복리후생비-피복제비(제조) | B35: 피복제비(제조) | C35: 고정비 | D35: 5103180 | E35: BT351 | F35: 0 | G35: =SUM(H35:S35) -> 0 | H35: =IFERROR(INDEX('[1]2024'!$A:$Q,MATCH($A$3&$D35,'[1]2024'!$B:$B,0),MATCH(H$4,'[1]2024'!$2:$2,0)),0)+IFERROR(INDEX('[1]2024'!$A:$Q,MATCH($B$3&$D35,'[1]2024'!$B:$B,0),MATCH(H$4,'[1]2024'!$2:$2,0)),0)++IFERROR(INDEX('[1]2024'!$A:$Q,MATCH($C$3&$D35,'[1]2024'!$B:$B,0),MATCH(H$4,'[1]2024'!$2:$2,0)),0)++IFERROR(INDEX('[1]2024'!$A:$Q,MATCH($D$3&$D35,'[1]2024'!$B:$B,0),MATCH(H$4,'[1]2024'!$2:$2,0)),0) -> 0 | I35: =IFERROR(INDEX('[1]2024'!$A:$Q,MATCH($A$3&$D35,'[1]2024'!$B:$B,0),MATCH(I$4,'[1]2024'!$2:$2,0)),0)+IFERROR(INDEX('[1]2024'!$A:$Q,MATCH($B$3&$D35,'[1]2024'!$B:$B,0),MATCH(I$4,'[1]2024'!$2:$2,0)),0)++IFERROR(INDEX('[1]2024'!$A:$Q,MATCH($C$3&$D35,'[1]2024'!$B:$B,0),MATCH(I$4,'[1]2024'!$2:$2,0)),0)++IFERROR(INDEX('[1]2024'!$A:$Q,MATCH($D$3&$D35,'[1]2024'!$B:$B,0),MATCH(I$4,'[1]2024'!$2:$2,0)),0) -> 0 | J35: =IFERROR(INDEX('[1]2024'!$A:$Q,MATCH($A$3&$D35,'[1]2024'!$B:$B,0),MATCH(J$4,'[1]2024'!$2:$2,0)),0)+IFERROR(INDEX('[1]2024'!$A:$Q,MATCH($B$3&$D35,'[1]2024'!$B:$B,0),MATCH(J$4,'[1]2024'!$2:$2,0)),0)++IFERROR(INDEX('[1]2024'!$A:$Q,MATCH($C$3&$D35,'[1]2024'!$B:$B,0),MATCH(J$4,'[1]2024'!$2:$2,0)),0)++IFERROR(INDEX('[1]2024'!$A:$Q,MATCH($D$3&$D35,'[1]2024'!$B:$B,0),MATCH(J$4,'[1]2024'!$2:$2,0)),0) -> 0 | K35: =IFERROR(INDEX('[1]2024'!$A:$Q,MATCH($A$3&$D35,'[1]2024'!$B:$B,0),MATCH(K$4,'[1]2024'!$2:$2,0)),0)+IFERROR(INDEX('[1]2024'!$A:$Q,MATCH($B$3&$D35,'[1]2024'!$B:$B,0),MATCH(K$4,'[1]2024'!$2:$2,0)),0)++IFERROR(INDEX('[1]2024'!$A:$Q,MATCH($C$3&$D35,'[1]2024'!$B:$B,0),MATCH(K$4,'[1]2024'!$2:$2,0)),0)++IFERROR(INDEX('[1]2024'!$A:$Q,MATCH($D$3&$D35,'[1]2024'!$B:$B,0),MATCH(K$4,'[1]2024'!$2:$2,0)),0) -> 0 | L35: =IFERROR(INDEX('[1]2024'!$A:$Q,MATCH($A$3&$D35,'[1]2024'!$B:$B,0),MATCH(L$4,'[1]2024'!$2:$2,0)),0)+IFERROR(INDEX('[1]2024'!$A:$Q,MATCH($B$3&$D35,'[1]2024'!$B:$B,0),MATCH(L$4,'[1]2024'!$2:$2,0)),0)++IFERROR(INDEX('[1]2024'!$A:$Q,MATCH($C$3&$D35,'[1]2024'!$B:$B,0),MATCH(L$4,'[1]2024'!$2:$2,0)),0)++IFERROR(INDEX('[1]2024'!$A:$Q,MATCH($D$3&$D35,'[1]2024'!$B:$B,0),MATCH(L$4,'[1]2024'!$2:$2,0)),0) -> 0 | M35: =IFERROR(INDEX('[1]2024'!$A:$Q,MATCH($A$3&$D35,'[1]2024'!$B:$B,0),MATCH(M$4,'[1]2024'!$2:$2,0)),0)+IFERROR(INDEX('[1]2024'!$A:$Q,MATCH($B$3&$D35,'[1]2024'!$B:$B,0),MATCH(M$4,'[1]2024'!$2:$2,0)),0)++IFERROR(INDEX('[1]2024'!$A:$Q,MATCH($C$3&$D35,'[1]2024'!$B:$B,0),MATCH(M$4,'[1]2024'!$2:$2,0)),0)++IFERROR(INDEX('[1]2024'!$A:$Q,MATCH($D$3&$D35,'[1]2024'!$B:$B,0),MATCH(M$4,'[1]2024'!$2:$2,0)),0) -> 0 | N35: =IFERROR(INDEX('[1]2024'!$A:$Q,MATCH($A$3&$D35,'[1]2024'!$B:$B,0),MATCH(N$4,'[1]2024'!$2:$2,0)),0)+IFERROR(INDEX('[1]2024'!$A:$Q,MATCH($B$3&$D35,'[1]2024'!$B:$B,0),MATCH(N$4,'[1]2024'!$2:$2,0)),0)++IFERROR(INDEX('[1]2024'!$A:$Q,MATCH($C$3&$D35,'[1]2024'!$B:$B,0),MATCH(N$4,'[1]2024'!$2:$2,0)),0)++IFERROR(INDEX('[1]2024'!$A:$Q,MATCH($D$3&$D35,'[1]2024'!$B:$B,0),MATCH(N$4,'[1]2024'!$2:$2,0)),0) -> 0 | O35: =IFERROR(INDEX('[1]2024'!$A:$Q,MATCH($A$3&$D35,'[1]2024'!$B:$B,0),MATCH(O$4,'[1]2024'!$2:$2,0)),0)+IFERROR(INDEX('[1]2024'!$A:$Q,MATCH($B$3&$D35,'[1]2024'!$B:$B,0),MATCH(O$4,'[1]2024'!$2:$2,0)),0)++IFERROR(INDEX('[1]2024'!$A:$Q,MATCH($C$3&$D35,'[1]2024'!$B:$B,0),MATCH(O$4,'[1]2024'!$2:$2,0)),0)++IFERROR(INDEX('[1]2024'!$A:$Q,MATCH($D$3&$D35,'[1]2024'!$B:$B,0),MATCH(O$4,'[1]2024'!$2:$2,0)),0) -> 0 | ... S35: =IFERROR(INDEX('[1]2024'!$A:$Q,MATCH($A$3&$D35,'[1]2024'!$B:$B,0),MATCH(S$4,'[1]2024'!$2:$2,0)),0)+IFERROR(INDEX('[1]2024'!$A:$Q,MATCH($B$3&$D35,'[1]2024'!$B:$B,0),MATCH(S$4,'[1]2024'!$2:$2,0)),0)++IFERROR(INDEX('[1]2024'!$A:$Q,MATCH($C$3&$D35,'[1]2024'!$B:$B,0),MATCH(S$4,'[1]2024'!$2:$2,0)),0)++IFERROR(INDEX('[1]2024'!$A:$Q,MATCH($D$3&$D35,'[1]2024'!$B:$B,0),MATCH(S$4,'[1]2024'!$2:$2,0)),0) -> 0 | T35: 0 | U35: =SUM(V35:AG35) -> 0 | V35: 0 | W35: 0 | X35: 0 | Y35: 0 | Z35: 0 | AA35: 0 | AB35: 0 | AC35: 0 | AD35: 0 | AE35: 0 | AF35: 0 | AG35: 0 | AH35: =송도공장장!AH35+제조팀!AH35+송도밸리데이션팀!AH35+송도생산지원팀!AH35+송도설비관리팀!AH35 -> 3600000 | AI35: =송도공장장!AI35+제조팀!AI35+송도밸리데이션팀!AI35+송도생산지원팀!AI35+송도설비관리팀!AI35 -> 300000 | AJ35: =송도공장장!AJ35+제조팀!AJ35+송도밸리데이션팀!AJ35+송도생산지원팀!AJ35+송도설비관리팀!AJ35 -> 300000 | AK35: =송도공장장!AK35+제조팀!AK35+송도밸리데이션팀!AK35+송도생산지원팀!AK35+송도설비관리팀!AK35 -> 300000 | AL35: =송도공장장!AL35+제조팀!AL35+송도밸리데이션팀!AL35+송도생산지원팀!AL35+송도설비관리팀!AL35 -> 300000 | AM35: =송도공장장!AM35+제조팀!AM35+송도밸리데이션팀!AM35+송도생산지원팀!AM35+송도설비관리팀!AM35 -> 300000 | AN35: =송도공장장!AN35+제조팀!AN35+송도밸리데이션팀!AN35+송도생산지원팀!AN35+송도설비관리팀!AN35 -> 300000 | AO35: =송도공장장!AO35+제조팀!AO35+송도밸리데이션팀!AO35+송도생산지원팀!AO35+송도설비관리팀!AO35 -> 300000 | ... AT35: =송도공장장!AT35+제조팀!AT35+송도밸리데이션팀!AT35+송도생산지원팀!AT35+송도설비관리팀!AT35 -> 300000 | AU35: =SUM(AI35:AK35) -> 900000 | AV35: =SUM(AL35:AN35) -> 900000 | AW35: =SUM(AO35:AQ35) -> 900000 | AX35: =SUM(AR35:AT35) -> 900000 | AY35: =IF($BC35="O",1.05*$AH35,$AH35) -> 3600000 | AZ35: =IF($BC35="O",1.05*$AY35,$AY35) -> 3600000 | BA35: =IF($BC35="O",1.05*$AZ35,$AZ35) -> 3600000 | BC35: X | BE35: 0 | BF35: 0 | BG35: 0 | BH35: =G35 -> 0
A36: 복리후생비-의료위생비(제조) | B36: 의료위생비(제조) | C36: 고정비 | D36: 5103170 | E36: BT242 | F36: 0 | G36: =SUM(H36:S36) -> 0 | H36: =IFERROR(INDEX('[1]2024'!$A:$Q,MATCH($A$3&$D36,'[1]2024'!$B:$B,0),MATCH(H$4,'[1]2024'!$2:$2,0)),0)+IFERROR(INDEX('[1]2024'!$A:$Q,MATCH($B$3&$D36,'[1]2024'!$B:$B,0),MATCH(H$4,'[1]2024'!$2:$2,0)),0)++IFERROR(INDEX('[1]2024'!$A:$Q,MATCH($C$3&$D36,'[1]2024'!$B:$B,0),MATCH(H$4,'[1]2024'!$2:$2,0)),0)++IFERROR(INDEX('[1]2024'!$A:$Q,MATCH($D$3&$D36,'[1]2024'!$B:$B,0),MATCH(H$4,'[1]2024'!$2:$2,0)),0) -> 0 | I36: =IFERROR(INDEX('[1]2024'!$A:$Q,MATCH($A$3&$D36,'[1]2024'!$B:$B,0),MATCH(I$4,'[1]2024'!$2:$2,0)),0)+IFERROR(INDEX('[1]2024'!$A:$Q,MATCH($B$3&$D36,'[1]2024'!$B:$B,0),MATCH(I$4,'[1]2024'!$2:$2,0)),0)++IFERROR(INDEX('[1]2024'!$A:$Q,MATCH($C$3&$D36,'[1]2024'!$B:$B,0),MATCH(I$4,'[1]2024'!$2:$2,0)),0)++IFERROR(INDEX('[1]2024'!$A:$Q,MATCH($D$3&$D36,'[1]2024'!$B:$B,0),MATCH(I$4,'[1]2024'!$2:$2,0)),0) -> 0 | J36: =IFERROR(INDEX('[1]2024'!$A:$Q,MATCH($A$3&$D36,'[1]2024'!$B:$B,0),MATCH(J$4,'[1]2024'!$2:$2,0)),0)+IFERROR(INDEX('[1]2024'!$A:$Q,MATCH($B$3&$D36,'[1]2024'!$B:$B,0),MATCH(J$4,'[1]2024'!$2:$2,0)),0)++IFERROR(INDEX('[1]2024'!$A:$Q,MATCH($C$3&$D36,'[1]2024'!$B:$B,0),MATCH(J$4,'[1]2024'!$2:$2,0)),0)++IFERROR(INDEX('[1]2024'!$A:$Q,MATCH($D$3&$D36,'[1]2024'!$B:$B,0),MATCH(J$4,'[1]2024'!$2:$2,0)),0) -> 0 | K36: =IFERROR(INDEX('[1]2024'!$A:$Q,MATCH($A$3&$D36,'[1]2024'!$B:$B,0),MATCH(K$4,'[1]2024'!$2:$2,0)),0)+IFERROR(INDEX('[1]2024'!$A:$Q,MATCH($B$3&$D36,'[1]2024'!$B:$B,0),MATCH(K$4,'[1]2024'!$2:$2,0)),0)++IFERROR(INDEX('[1]2024'!$A:$Q,MATCH($C$3&$D36,'[1]2024'!$B:$B,0),MATCH(K$4,'[1]2024'!$2:$2,0)),0)++IFERROR(INDEX('[1]2024'!$A:$Q,MATCH($D$3&$D36,'[1]2024'!$B:$B,0),MATCH(K$4,'[1]2024'!$2:$2,0)),0) -> 0 | L36: =IFERROR(INDEX('[1]2024'!$A:$Q,MATCH($A$3&$D36,'[1]2024'!$B:$B,0),MATCH(L$4,'[1]2024'!$2:$2,0)),0)+IFERROR(INDEX('[1]2024'!$A:$Q,MATCH($B$3&$D36,'[1]2024'!$B:$B,0),MATCH(L$4,'[1]2024'!$2:$2,0)),0)++IFERROR(INDEX('[1]2024'!$A:$Q,MATCH($C$3&$D36,'[1]2024'!$B:$B,0),MATCH(L$4,'[1]2024'!$2:$2,0)),0)++IFERROR(INDEX('[1]2024'!$A:$Q,MATCH($D$3&$D36,'[1]2024'!$B:$B,0),MATCH(L$4,'[1]2024'!$2:$2,0)),0) -> 0 | M36: =IFERROR(INDEX('[1]2024'!$A:$Q,MATCH($A$3&$D36,'[1]2024'!$B:$B,0),MATCH(M$4,'[1]2024'!$2:$2,0)),0)+IFERROR(INDEX('[1]2024'!$A:$Q,MATCH($B$3&$D36,'[1]2024'!$B:$B,0),MATCH(M$4,'[1]2024'!$2:$2,0)),0)++IFERROR(INDEX('[1]2024'!$A:$Q,MATCH($C$3&$D36,'[1]2024'!$B:$B,0),MATCH(M$4,'[1]2024'!$2:$2,0)),0)++IFERROR(INDEX('[1]2024'!$A:$Q,MATCH($D$3&$D36,'[1]2024'!$B:$B,0),MATCH(M$4,'[1]2024'!$2:$2,0)),0) -> 0 | N36: =IFERROR(INDEX('[1]2024'!$A:$Q,MATCH($A$3&$D36,'[1]2024'!$B:$B,0),MATCH(N$4,'[1]2024'!$2:$2,0)),0)+IFERROR(INDEX('[1]2024'!$A:$Q,MATCH($B$3&$D36,'[1]2024'!$B:$B,0),MATCH(N$4,'[1]2024'!$2:$2,0)),0)++IFERROR(INDEX('[1]2024'!$A:$Q,MATCH($C$3&$D36,'[1]2024'!$B:$B,0),MATCH(N$4,'[1]2024'!$2:$2,0)),0)++IFERROR(INDEX('[1]2024'!$A:$Q,MATCH($D$3&$D36,'[1]2024'!$B:$B,0),MATCH(N$4,'[1]2024'!$2:$2,0)),0) -> 0 | O36: =IFERROR(INDEX('[1]2024'!$A:$Q,MATCH($A$3&$D36,'[1]2024'!$B:$B,0),MATCH(O$4,'[1]2024'!$2:$2,0)),0)+IFERROR(INDEX('[1]2024'!$A:$Q,MATCH($B$3&$D36,'[1]2024'!$B:$B,0),MATCH(O$4,'[1]2024'!$2:$2,0)),0)++IFERROR(INDEX('[1]2024'!$A:$Q,MATCH($C$3&$D36,'[1]2024'!$B:$B,0),MATCH(O$4,'[1]2024'!$2:$2,0)),0)++IFERROR(INDEX('[1]2024'!$A:$Q,MATCH($D$3&$D36,'[1]2024'!$B:$B,0),MATCH(O$4,'[1]2024'!$2:$2,0)),0) -> 0 | ... S36: =IFERROR(INDEX('[1]2024'!$A:$Q,MATCH($A$3&$D36,'[1]2024'!$B:$B,0),MATCH(S$4,'[1]2024'!$2:$2,0)),0)+IFERROR(INDEX('[1]2024'!$A:$Q,MATCH($B$3&$D36,'[1]2024'!$B:$B,0),MATCH(S$4,'[1]2024'!$2:$2,0)),0)++IFERROR(INDEX('[1]2024'!$A:$Q,MATCH($C$3&$D36,'[1]2024'!$B:$B,0),MATCH(S$4,'[1]2024'!$2:$2,0)),0)++IFERROR(INDEX('[1]2024'!$A:$Q,MATCH($D$3&$D36,'[1]2024'!$B:$B,0),MATCH(S$4,'[1]2024'!$2:$2,0)),0) -> 0 | T36: 0 | U36: =SUM(V36:AG36) -> 0 | V36: 0 | W36: 0 | X36: 0 | Y36: 0 | Z36: 0 | AA36: 0 | AB36: 0 | AC36: 0 | AD36: 0 | AE36: 0 | AF36: 0 | AG36: 0 | AH36: =송도공장장!AH36+제조팀!AH36+송도밸리데이션팀!AH36+송도생산지원팀!AH36+송도설비관리팀!AH36 -> 10100000 | AI36: =송도공장장!AI36+제조팀!AI36+송도밸리데이션팀!AI36+송도생산지원팀!AI36+송도설비관리팀!AI36 -> 100000 | AJ36: =송도공장장!AJ36+제조팀!AJ36+송도밸리데이션팀!AJ36+송도생산지원팀!AJ36+송도설비관리팀!AJ36 -> 100000 | AK36: =송도공장장!AK36+제조팀!AK36+송도밸리데이션팀!AK36+송도생산지원팀!AK36+송도설비관리팀!AK36 -> 100000 | AL36: =송도공장장!AL36+제조팀!AL36+송도밸리데이션팀!AL36+송도생산지원팀!AL36+송도설비관리팀!AL36 -> 2100000 | AM36: =송도공장장!AM36+제조팀!AM36+송도밸리데이션팀!AM36+송도생산지원팀!AM36+송도설비관리팀!AM36 -> 100000 | AN36: =송도공장장!AN36+제조팀!AN36+송도밸리데이션팀!AN36+송도생산지원팀!AN36+송도설비관리팀!AN36 -> 100000 | AO36: =송도공장장!AO36+제조팀!AO36+송도밸리데이션팀!AO36+송도생산지원팀!AO36+송도설비관리팀!AO36 -> 100000 | ... AT36: =송도공장장!AT36+제조팀!AT36+송도밸리데이션팀!AT36+송도생산지원팀!AT36+송도설비관리팀!AT36 -> 100000 | AU36: =SUM(AI36:AK36) -> 300000 | AV36: =SUM(AL36:AN36) -> 2300000 | AW36: =SUM(AO36:AQ36) -> 7200000 | AX36: =SUM(AR36:AT36) -> 300000 | AY36: =IF($BC36="O",1.05*$AH36,$AH36) -> 10100000 | AZ36: =IF($BC36="O",1.05*$AY36,$AY36) -> 10100000 | BA36: =IF($BC36="O",1.05*$AZ36,$AZ36) -> 10100000 | BC36: X | BE36: 0 | BF36: 0 | BG36: 0 | BH36: =G36 -> 0
A37: 복리후생비-단체시상비(제조) | B37: 단체시상비(제조) | C37: 고정비 | D37: 5103160 | E37: BT066 | F37: 0 | G37: =SUM(H37:S37) -> 0 | H37: =IFERROR(INDEX('[1]2024'!$A:$Q,MATCH($A$3&$D37,'[1]2024'!$B:$B,0),MATCH(H$4,'[1]2024'!$2:$2,0)),0)+IFERROR(INDEX('[1]2024'!$A:$Q,MATCH($B$3&$D37,'[1]2024'!$B:$B,0),MATCH(H$4,'[1]2024'!$2:$2,0)),0)++IFERROR(INDEX('[1]2024'!$A:$Q,MATCH($C$3&$D37,'[1]2024'!$B:$B,0),MATCH(H$4,'[1]2024'!$2:$2,0)),0)++IFERROR(INDEX('[1]2024'!$A:$Q,MATCH($D$3&$D37,'[1]2024'!$B:$B,0),MATCH(H$4,'[1]2024'!$2:$2,0)),0) -> 0 | I37: =IFERROR(INDEX('[1]2024'!$A:$Q,MATCH($A$3&$D37,'[1]2024'!$B:$B,0),MATCH(I$4,'[1]2024'!$2:$2,0)),0)+IFERROR(INDEX('[1]2024'!$A:$Q,MATCH($B$3&$D37,'[1]2024'!$B:$B,0),MATCH(I$4,'[1]2024'!$2:$2,0)),0)++IFERROR(INDEX('[1]2024'!$A:$Q,MATCH($C$3&$D37,'[1]2024'!$B:$B,0),MATCH(I$4,'[1]2024'!$2:$2,0)),0)++IFERROR(INDEX('[1]2024'!$A:$Q,MATCH($D$3&$D37,'[1]2024'!$B:$B,0),MATCH(I$4,'[1]2024'!$2:$2,0)),0) -> 0 | J37: =IFERROR(INDEX('[1]2024'!$A:$Q,MATCH($A$3&$D37,'[1]2024'!$B:$B,0),MATCH(J$4,'[1]2024'!$2:$2,0)),0)+IFERROR(INDEX('[1]2024'!$A:$Q,MATCH($B$3&$D37,'[1]2024'!$B:$B,0),MATCH(J$4,'[1]2024'!$2:$2,0)),0)++IFERROR(INDEX('[1]2024'!$A:$Q,MATCH($C$3&$D37,'[1]2024'!$B:$B,0),MATCH(J$4,'[1]2024'!$2:$2,0)),0)++IFERROR(INDEX('[1]2024'!$A:$Q,MATCH($D$3&$D37,'[1]2024'!$B:$B,0),MATCH(J$4,'[1]2024'!$2:$2,0)),0) -> 0 | K37: =IFERROR(INDEX('[1]2024'!$A:$Q,MATCH($A$3&$D37,'[1]2024'!$B:$B,0),MATCH(K$4,'[1]2024'!$2:$2,0)),0)+IFERROR(INDEX('[1]2024'!$A:$Q,MATCH($B$3&$D37,'[1]2024'!$B:$B,0),MATCH(K$4,'[1]2024'!$2:$2,0)),0)++IFERROR(INDEX('[1]2024'!$A:$Q,MATCH($C$3&$D37,'[1]2024'!$B:$B,0),MATCH(K$4,'[1]2024'!$2:$2,0)),0)++IFERROR(INDEX('[1]2024'!$A:$Q,MATCH($D$3&$D37,'[1]2024'!$B:$B,0),MATCH(K$4,'[1]2024'!$2:$2,0)),0) -> 0 | L37: =IFERROR(INDEX('[1]2024'!$A:$Q,MATCH($A$3&$D37,'[1]2024'!$B:$B,0),MATCH(L$4,'[1]2024'!$2:$2,0)),0)+IFERROR(INDEX('[1]2024'!$A:$Q,MATCH($B$3&$D37,'[1]2024'!$B:$B,0),MATCH(L$4,'[1]2024'!$2:$2,0)),0)++IFERROR(INDEX('[1]2024'!$A:$Q,MATCH($C$3&$D37,'[1]2024'!$B:$B,0),MATCH(L$4,'[1]2024'!$2:$2,0)),0)++IFERROR(INDEX('[1]2024'!$A:$Q,MATCH($D$3&$D37,'[1]2024'!$B:$B,0),MATCH(L$4,'[1]2024'!$2:$2,0)),0) -> 0 | M37: =IFERROR(INDEX('[1]2024'!$A:$Q,MATCH($A$3&$D37,'[1]2024'!$B:$B,0),MATCH(M$4,'[1]2024'!$2:$2,0)),0)+IFERROR(INDEX('[1]2024'!$A:$Q,MATCH($B$3&$D37,'[1]2024'!$B:$B,0),MATCH(M$4,'[1]2024'!$2:$2,0)),0)++IFERROR(INDEX('[1]2024'!$A:$Q,MATCH($C$3&$D37,'[1]2024'!$B:$B,0),MATCH(M$4,'[1]2024'!$2:$2,0)),0)++IFERROR(INDEX('[1]2024'!$A:$Q,MATCH($D$3&$D37,'[1]2024'!$B:$B,0),MATCH(M$4,'[1]2024'!$2:$2,0)),0) -> 0 | N37: =IFERROR(INDEX('[1]2024'!$A:$Q,MATCH($A$3&$D37,'[1]2024'!$B:$B,0),MATCH(N$4,'[1]2024'!$2:$2,0)),0)+IFERROR(INDEX('[1]2024'!$A:$Q,MATCH($B$3&$D37,'[1]2024'!$B:$B,0),MATCH(N$4,'[1]2024'!$2:$2,0)),0)++IFERROR(INDEX('[1]2024'!$A:$Q,MATCH($C$3&$D37,'[1]2024'!$B:$B,0),MATCH(N$4,'[1]2024'!$2:$2,0)),0)++IFERROR(INDEX('[1]2024'!$A:$Q,MATCH($D$3&$D37,'[1]2024'!$B:$B,0),MATCH(N$4,'[1]2024'!$2:$2,0)),0) -> 0 | O37: =IFERROR(INDEX('[1]2024'!$A:$Q,MATCH($A$3&$D37,'[1]2024'!$B:$B,0),MATCH(O$4,'[1]2024'!$2:$2,0)),0)+IFERROR(INDEX('[1]2024'!$A:$Q,MATCH($B$3&$D37,'[1]2024'!$B:$B,0),MATCH(O$4,'[1]2024'!$2:$2,0)),0)++IFERROR(INDEX('[1]2024'!$A:$Q,MATCH($C$3&$D37,'[1]2024'!$B:$B,0),MATCH(O$4,'[1]2024'!$2:$2,0)),0)++IFERROR(INDEX('[1]2024'!$A:$Q,MATCH($D$3&$D37,'[1]2024'!$B:$B,0),MATCH(O$4,'[1]2024'!$2:$2,0)),0) -> 0 | ... S37: =IFERROR(INDEX('[1]2024'!$A:$Q,MATCH($A$3&$D37,'[1]2024'!$B:$B,0),MATCH(S$4,'[1]2024'!$2:$2,0)),0)+IFERROR(INDEX('[1]2024'!$A:$Q,MATCH($B$3&$D37,'[1]2024'!$B:$B,0),MATCH(S$4,'[1]2024'!$2:$2,0)),0)++IFERROR(INDEX('[1]2024'!$A:$Q,MATCH($C$3&$D37,'[1]2024'!$B:$B,0),MATCH(S$4,'[1]2024'!$2:$2,0)),0)++IFERROR(INDEX('[1]2024'!$A:$Q,MATCH($D$3&$D37,'[1]2024'!$B:$B,0),MATCH(S$4,'[1]2024'!$2:$2,0)),0) -> 0 | T37: 0 | U37: =SUM(V37:AG37) -> 0 | V37: 0 | W37: 0 | X37: 0 | Y37: 0 | Z37: 0 | AA37: 0 | AB37: 0 | AC37: 0 | AD37: 0 | AE37: 0 | AF37: 0 | AG37: 0 | AH37: =송도공장장!AH37+제조팀!AH37+송도밸리데이션팀!AH37+송도생산지원팀!AH37+송도설비관리팀!AH37 -> 0 | AI37: =송도공장장!AI37+제조팀!AI37+송도밸리데이션팀!AI37+송도생산지원팀!AI37+송도설비관리팀!AI37 -> 0 | AJ37: =송도공장장!AJ37+제조팀!AJ37+송도밸리데이션팀!AJ37+송도생산지원팀!AJ37+송도설비관리팀!AJ37 -> 0 | AK37: =송도공장장!AK37+제조팀!AK37+송도밸리데이션팀!AK37+송도생산지원팀!AK37+송도설비관리팀!AK37 -> 0 | AL37: =송도공장장!AL37+제조팀!AL37+송도밸리데이션팀!AL37+송도생산지원팀!AL37+송도설비관리팀!AL37 -> 0 | AM37: =송도공장장!AM37+제조팀!AM37+송도밸리데이션팀!AM37+송도생산지원팀!AM37+송도설비관리팀!AM37 -> 0 | AN37: =송도공장장!AN37+제조팀!AN37+송도밸리데이션팀!AN37+송도생산지원팀!AN37+송도설비관리팀!AN37 -> 0 | AO37: =송도공장장!AO37+제조팀!AO37+송도밸리데이션팀!AO37+송도생산지원팀!AO37+송도설비관리팀!AO37 -> 0 | ... AT37: =송도공장장!AT37+제조팀!AT37+송도밸리데이션팀!AT37+송도생산지원팀!AT37+송도설비관리팀!AT37 -> 0 | AU37: =SUM(AI37:AK37) -> 0 | AV37: =SUM(AL37:AN37) -> 0 | AW37: =SUM(AO37:AQ37) -> 0 | AX37: =SUM(AR37:AT37) -> 0 | AY37: =IF($BC37="O",1.05*$AH37,$AH37) -> 0 | AZ37: =IF($BC37="O",1.05*$AY37,$AY37) -> 0 | BA37: =IF($BC37="O",1.05*$AZ37,$AZ37) -> 0 | BC37: X | BE37: 0 | BF37: 0 | BG37: 0 | BH37: =G37 -> 0
